Workbook

Sheet Board GX
A1: XFORCE EMS - ENGINEERING BOM RELEASE TEMPLATE
A2: Project Name | D2: CAMBOX V4- RK3562 | I2: PCB Rev | J2: Gerber_CAMBOX_GX_lot500_2505 | N2: Dessigned By | Q2: Đỗ Việt Đức | U2: Customer | W2: VNET
A3: Product Name | D3: CAMBOX V4- RK3562 | I3: BOM Rev | J3: BOM_CameraBox_2026-04-14 2205 | N3: Approved By | Q3: Cấn Văn Lịch | U3: Modified Date
A4: Board Name | D4: Board GX | I4: Lot Qty | J4: 500 | N4: Date Created | Q4: 46168 | U4: Change Ref / ECN No. | W4: Change Ref: BOM_CameraBox_2026-04-14 new 250526.xlsx
C5: select | D5: fcn | E5: fcn | F5: fcn | G5: must fill | H5: select | I5: must fill | J5: must fill | K5: select | L5: select | N5: must fill | O5: fcn | P5: fcn | Q5: must fill | R5: must fill | S5: must fill | T5: must fill | U5: select | V5: select | W5: select | X5: select | Y5: select | AA5: must fill | AG5: Lịch CV rà soát
A6: No | B6: PivotCol | C6: BOM Level | D6: Board Name | E6: PCB Rev | F6: BOM Rev | G6: RefDes | H6: Category | I6: Description | J6: Package / Footprint | K6: Mounting type | L6: Mount Status' | M6: Unit | N6: Qty/Set | O6: Board Qty | P6: Total Engineer Qty | Q6: Manufacturer 1 | R6: PN1 | S6: Manufacturer 2 | T6: PN2 | U6: AVL Status | V6: Substitution Rule | W6: Critical Level | X6: Release Status | Y6: Supply Type | Z6: Internal Code | AA6: Ref Supplier | AB6: Engineer Note | AC6: Change Note | AD6: Ref Link / Datasheet | AE6: SL đã có trong kho chị HÀ | AF6: SL cần mua | AG6: SL VNET Đã Bàn Giao CHO XFORCE | AH6: SL VNET dự kiến Bàn giao lần 2 | AI6: SL XF EMS đã mua bổ sung đợt 1 | AJ6: SL cần mua bổ sung đợt 2
A7: =ROW()-6 -> 1 | B7: =R7 -> C0603X5R105K500NT | C7: L1-PCBA | D7: =$D$4 -> Board GX | E7: =$J$2 -> Gerber_CAMBOX_GX_lot500_2505 | F7: =$J$3 -> BOM_CameraBox_2026-04-14 2205 | G7: C1, C2, C3, C4 | H7: Capacitor | I7: CAP CER 1UF 50V X5R 0603 | J7: 0603 | K7: SMD | L7: Mounted | M7: pcs | N7: 4 | O7: =$J$4 -> 500 | P7: =IF($N7="","",$N7*$O7) -> 2000 | Q7: Hottech | R7: C0603X5R105K500NT | S7: Samsung Electro-Mechanics | T7: CL10A105KB8NNNC | U7: Approved | V7: Approval Required | W7: Normal / Low | X7: Released | Y7: XFEMS Buy | AA7: LCSC | AE7: 0 | AF7: =P7-AE7 -> 2000 | AH7: =VLOOKUP(B7,'VNET-XF_dự kiến lần 2'!$B$2:$D$42,3,0)-VLOOKUP(B7,'Board RK3562'!$B$7:$AH$149,33,0) -> 0 | AI7: 0 | AJ7: =P7-SUM(AG7:AI7) -> 2000
A8: =ROW()-6 -> 2 | B8: =R8 -> 3.0-2*2A | C8: L1-PCBA | D8: =$D$4 -> Board GX | E8: =$J$2 -> Gerber_CAMBOX_GX_lot500_2505 | F8: =$J$3 -> BOM_CameraBox_2026-04-14 2205 | G8: J7, J9, J10, J11, J12, J13 | H8: Connector | I8: 2x2P 4P Micro-Fit(MX 3.0) 3mm 2 2 3mm Direct Insert Plugin,P=3mm Wire To Board Connector ROHS | K8: SMD | L8: Mounted | M8: pcs | N8: 6 | O8: =$J$4 -> 500 | P8: =IF($N8="","",$N8*$O8) -> 3000 | Q8: BOOMELE(Boom Precision Elec) | R8: 3.0-2*2A | U8: Approved | V8: Approval Required | W8: Normal / Low | X8: Released | Y8: XFEMS Buy | AA8: LCSC | AE8: 3125 | AF8: =P8-AE8 -> -125 | AI8: 0 | AJ8: =P8-SUM(AG8:AI8) -> 3000
A9: =ROW()-6 -> 3 | B9: =R9 -> X4621WRS-2x06I-C40D64 | C9: L1-PCBA | D9: =$D$4 -> Board GX | E9: =$J$2 -> Gerber_CAMBOX_GX_lot500_2505 | F9: =$J$3 -> BOM_CameraBox_2026-04-14 2205 | G9: J8, J14, J15 | H9: Connector | I9: 2x6P 12P Gold Brass -40℃~+105℃ Pin Header Black 2mm 2mm 250V 3A 2 2mm SMD,P=2mm Headers, Male Pins ROHS | K9: SMD | L9: Mounted | M9: pcs | N9: 3 | O9: =$J$4 -> 500 | P9: =IF($N9="","",$N9*$O9) -> 1500 | Q9: XKB Connection | R9: X4621WRS-2x06I-C40D64 | S9: XKB Connection | T9: X4621WRS-2x03I-C40D64 | U9: Approved | V9: Approval Required | W9: Normal / Low | X9: Released | Y9: XFEMS Buy | AA9: LCSC | AE9: 1500 | AF9: =P9-AE9 -> 0 | AI9: 0 | AJ9: =P9-SUM(AG9:AI9) -> 1500
A10: =ROW()-6 -> 4 | B10: =R10 -> SI2333CDS | C10: L1-PCBA | D10: =$D$4 -> Board GX | E10: =$J$2 -> Gerber_CAMBOX_GX_lot500_2505 | F10: =$J$3 -> BOM_CameraBox_2026-04-14 2205 | G10: Q1, Q2, Q5, Q6 | H10: MOSFET | I10: SOT-23-3 MOSFETs P-Chanel ROHS | K10: SMD | L10: Mounted | M10: pcs | N10: 4 | O10: =$J$4 -> 500 | P10: =IF($N10="","",$N10*$O10) -> 2000 | Q10: TECH PUBLIC | R10: SI2333CDS | U10: Approved | V10: Approval Required | W10: Normal / Low | X10: Released | Y10: XFEMS Buy | AA10: LCSC | AB10: VNET bàn giao tổng cộng 3470pcs, mạch RK3562 cần 3000pcs, mạch GX cần 2000pcs | AE10: 1500 | AF10: =P10-AE10 -> 500 | AG10: =VLOOKUP(B10,'VNET-XF-2105'!$B$12:$D$145,3,0)-VLOOKUP(B10,'Board RK3562'!$R$7:$AG$149,16,0) -> 0 | AH10: =VLOOKUP(B10,'VNET-XF_dự kiến lần 2'!$B$2:$D$42,3,0)-VLOOKUP(B10,'Board RK3562'!$B$7:$AH$149,33,0) -> 470 | AI10: 0 | AJ10: =P10-SUM(AG10:AI10) -> 1530
A11: =ROW()-6 -> 5 | B11: =R11 -> RC0402FR-0710KL | C11: L1-PCBA | D11: =$D$4 -> Board GX | E11: =$J$2 -> Gerber_CAMBOX_GX_lot500_2505 | F11: =$J$3 -> BOM_CameraBox_2026-04-14 2205 | G11: R1, R2, R7, R8, | H11: Resistor | I11: 62.5mW Thick Film Resistor 50V ±100ppm/℃ ±1% 10kΩ 0402 Chip Resistor - Surface Mount ROHS | J11: 0402 | K11: SMD | L11: Mounted | M11: pcs | N11: 4 | O11: =$J$4 -> 500 | P11: =IF($N11="","",$N11*$O11) -> 2000 | Q11: Yageo | R11: RC0402FR-0710KL | U11: Approved | V11: Approval Required | W11: Normal / Low | X11: Released | Y11: XFEMS Buy | AA11: LCSC | AE11: 2000 | AF11: =P11-AE11 -> 0 | AG11: =VLOOKUP(B11,'VNET-XF-2105'!$B$12:$D$145,3,0)-VLOOKUP(B11,'Board RK3562'!$R$7:$AG$149,16,0) -> 1090 | AI11: 0 | AJ11: =P11-SUM(AG11:AI11) -> 910
A12: =ROW()-6 -> 6 | B12: =R12 -> RC0402FR-074K7L | C12: L1-PCBA | D12: =$D$4 -> Board GX | E12: =$J$2 -> Gerber_CAMBOX_GX_lot500_2505 | F12: =$J$3 -> BOM_CameraBox_2026-04-14 2205 | G12: R3, R4, R9, R10 | H12: Resistor | I12: 62.5mW Thick Film Resistors 50V ±100ppm/℃ ±1% 4.7kΩ 0402 Chip Resistor - Surface Mount ROHS | J12: 0402 | K12: SMD | L12: Mounted | M12: pcs | N12: 4 | O12: =$J$4 -> 500 | P12: =IF($N12="","",$N12*$O12) -> 2000 | Q12: Yageo | R12: RC0402FR-074K7L | U12: Approved | V12: Approval Required | W12: Normal / Low | X12: Released | Y12: XFEMS Buy | AA12: LCSC | AE12: 0 | AF12: =P12-AE12 -> 2000 | AG12: =VLOOKUP(B12,'VNET-XF-2105'!$B$12:$D$145,3,0)-VLOOKUP(B12,'Board RK3562'!$R$7:$AG$149,16,0) -> 0 | AH12: =VLOOKUP(B12,'VNET-XF_dự kiến lần 2'!$B$2:$D$42,3,0)-VLOOKUP(B12,'Board RK3562'!$B$7:$AH$149,33,0) -> 1805 | AI12: 0 | AJ12: =P12-SUM(AG12:AI12) -> 195
A13: =ROW()-6 -> 7 | B13: =R13 -> RC0402FR-0747KL | C13: L1-PCBA | D13: =$D$4 -> Board GX | E13: =$J$2 -> Gerber_CAMBOX_GX_lot500_2505 | F13: =$J$3 -> BOM_CameraBox_2026-04-14 2205 | G13: R5, R6, R11, R12 | H13: Resistor | I13: 62.5mW Thick Film Resistor 50V ±100ppm/℃ ±1% 47kΩ 0402 Chip Resistor - Surface Mount ROHS | J13: 0402 | K13: SMD | L13: Mounted | M13: pcs | N13: 4 | O13: =$J$4 -> 500 | P13: =IF($N13="","",$N13*$O13) -> 2000 | Q13: Yageo | R13: RC0402FR-0747KL | U13: Approved | V13: Approval Required | W13: Normal / Low | X13: Released | Y13: XFEMS Buy | AA13: LCSC | AE13: 1500 | AF13: =P13-AE13 -> 500 | AG13: =VLOOKUP(B13,'VNET-XF-2105'!$B$12:$D$145,3,0)-VLOOKUP(B13,'Board RK3562'!$R$7:$AG$149,16,0) -> 420 | AH13: =VLOOKUP(B13,'VNET-XF_dự kiến lần 2'!$B$2:$D$42,3,0)-VLOOKUP(B13,'Board RK3562'!$B$7:$AH$149,33,0) -> 500 | AI13: 0 | AJ13: =P13-SUM(AG13:AI13) -> 1080
A14: =ROW()-6 -> 8 | B14: =R14 -> MMBTA05LT1G | C14: L1-PCBA | D14: =$D$4 -> Board GX | E14: =$J$2 -> Gerber_CAMBOX_GX_lot500_2505 | F14: =$J$3 -> BOM_CameraBox_2026-04-14 2205 | G14: Q3, Q4, Q7, Q8 | H14: Transistor | I14: TRANS NPN 60V 0.5A SOT23 | K14: SMD | L14: Mounted | M14: pcs | N14: 4 | O14: =$J$4 -> 500 | P14: =IF($N14="","",$N14*$O14) -> 2000 | Q14: ON Semiconductor | R14: MMBTA05LT1G | U14: Approved | V14: Approval Required | W14: Normal / Low | X14: Released | Y14: XFEMS Buy | AA14: LCSC | AE14: 2000 | AF14: =P14-AE14 -> 0 | AI14: 0 | AJ14: =P14-SUM(AG14:AI14) -> 2000
A15: =ROW()-6 -> 9 | B15: =R15 -> GX12-2P | C15: L1-PCBA | D15: =$D$4 -> Board GX | E15: =$J$2 -> Gerber_CAMBOX_GX_lot500_2505 | F15: =$J$3 -> BOM_CameraBox_2026-04-14 2205 | G15: J1 | H15: Connector | I15: Giắc GX12-2P 2 Chân (Đực) | K15: TH | L15: Mounted | M15: pcs | N15: 1 | O15: =$J$4 -> 500 | P15: =IF($N15="","",$N15*$O15) -> 500 | Q15: LKTC | R15: GX12-2P | U15: Approved | V15: No Substitute | W15: Important / High | X15: Released | Y15: XFEMS Buy | AA15: Aliexpress | AE15: 0 | AF15: =P15-AE15 -> 500 | AI15: 0 | AJ15: =P15-SUM(AG15:AI15) -> 500
A16: =ROW()-6 -> 10 | B16: =R16 -> GX12-4P | C16: L1-PCBA | D16: =$D$4 -> Board GX | E16: =$J$2 -> Gerber_CAMBOX_GX_lot500_2505 | F16: =$J$3 -> BOM_CameraBox_2026-04-14 2205 | G16: J2, J3, J5, J6 | H16: Connector | I16: Giắc GX12-4P 12mm 4 Chân (Đực) | K16: TH | L16: Mounted | M16: pcs | N16: 4 | O16: =$J$4 -> 500 | P16: =IF($N16="","",$N16*$O16) -> 2000 | Q16: LKTC | R16: GX12-4P | U16: Approved | V16: No Substitute | W16: Important / High | X16: Released | Y16: XFEMS Buy | AA16: Aliexpress | AE16: 0 | AF16: =P16-AE16 -> 2000 | AI16: 0 | AJ16: =P16-SUM(AG16:AI16) -> 2000
A17: =ROW()-6 -> 11 | B17: =R17 -> JLCPCB | C17: L1-PCBA | D17: =$D$4 -> Board GX | E17: =$J$2 -> Gerber_CAMBOX_GX_lot500_2505 | F17: =$J$3 -> BOM_CameraBox_2026-04-14 2205 | H17: PCB | I17: PCB, 2 layer, 113.94 mm* 23.58 mm, PCB Thickness: 1.6mm, Gerber_Camerabox-gx_2025-11-24_Y2413 | L17: Mounted | M17: pcs | N17: 1 | O17: =$J$4 -> 500 | P17: =IF($N17="","",$N17*$O17) -> 500 | Q17: JLCPCB | R17: JLCPCB | U17: Approved | V17: No Substitute | W17: Important / High | X17: Released | Y17: Do Not Buy | AA17: JLCPCB | AB17: XF EMS đã mua bổ sung đợt 1 | AE17: 0 | AF17: =P17 -> 500 | AI17: 500 | AJ17: =P17-SUM(AG17:AI17) -> 0
A18: =ROW()-6 -> 12 | B18: =R18 -> 0 | C18: L1-PCBA | D18: =$D$4 -> Board GX | E18: =$J$2 -> Gerber_CAMBOX_GX_lot500_2505 | F18: =$J$3 -> BOM_CameraBox_2026-04-14 2205 | H18: Stencil | I18: Stencil GX | L18: Mounted | M18: pcs | N18: 1 | O18: =$J$4 -> 500 | P18: =IF($N18="","",$N18*$O18) -> 500 | U18: Not Yet Approved | V18: No Substitute | W18: Important / High | X18: Released | Y18: Do Not Buy | AB18: Naisi là đối tác gia công SMT sẽ mua | AC18: Thêm 1, chưa rõ nhà cung cấp | AE18: 0 | AF18: 1 | AI18: 0 | AJ18: =P18-SUM(AG18:AI18) -> 500
A19: =ROW()-6 -> 13 | B19: =R19 -> MKP | C19: L1-PCBA | D19: =$D$4 -> Board GX | E19: =$J$2 -> Gerber_CAMBOX_GX_lot500_2505 | F19: =$J$3 -> BOM_CameraBox_2026-04-14 2205 | H19: SMT | I19: SMT mạch GX | L19: Mounted | M19: pcs | N19: 1 | O19: =$J$4 -> 500 | P19: =IF($N19="","",$N19*$O19) -> 500 | Q19: MKP | R19: MKP | U19: Not Yet Approved | V19: No Substitute | W19: Important / High | X19: Released | Y19: Do Not Buy | AA19: MKP | AB19: Naisi SMT | AC19: Thêm SMT | AE19: 0 | AF19: =P19 -> 500 | AI19: 0 | AJ19: =P19-SUM(AG19:AI19) -> 500

Sheet BOX_CAM
A1: XFORCE EMS - ENGINEERING BOM RELEASE TEMPLATE
A2: Project Name | D2: CAMBOX V4- RK3562 | I2: PCB Rev | N2: Dessigned By | Q2: Đỗ Việt Đức | U2: Customer | W2: VNET
A3: Product Name | D3: CAMBOX V4- RK3562 | I3: BOM Rev | J3: BOM_CameraBox_2026-04-14 2205 | N3: Approved By | Q3: Cấn Văn Lịch | U3: Modified Date
A4: Board Name | D4: BOX_CAM | I4: Lot Qty | J4: 500 | N4: Date Created | Q4: 46168 | U4: Change Ref / ECN No. | W4: Change Ref: BOM_CameraBox_2026-04-14 new 250526.xlsx
C5: select | D5: fcn | E5: fcn | F5: fcn | G5: must fill | H5: select | I5: must fill | J5: must fill | K5: select | L5: select | N5: must fill | O5: fcn | P5: fcn | Q5: must fill | R5: must fill | S5: must fill | T5: must fill | U5: select | V5: select | W5: select | X5: select | Y5: select | AA5: must fill | AG5: Lịch CV rà soát
A6: No | B6: PivotCol | C6: BOM Level | D6: Board Name | E6: PCB Rev | F6: BOM Rev | G6: RefDes | H6: Category | I6: Description | J6: Package / Footprint | K6: Mounting type | L6: Mount Status' | M6: Unit | N6: Qty/Set | O6: Board Qty | P6: Total Engineer Qty | Q6: Manufacturer 1 | R6: PN1 | S6: Manufacturer 2 | T6: PN2 | U6: AVL Status | V6: Substitution Rule | W6: Critical Level | X6: Release Status | Y6: Supply Type | Z6: Internal Code | AA6: Ref Supplier | AB6: Engineer Note | AC6: Change Note | AD6: Ref Link / Datasheet | AE6: SL đã có trong kho chị HÀ | AF6: SL cần mua | AG6: SL VNET Đã Bàn Giao CHO XFORCE | AH6: SL VNET dự kiến Bàn giao lần 2 | AI6: SL XF EMS đã mua bổ sung đợt 1 | AJ6: SL cần mua bổ sung đợt 2
A7: =ROW()-6 -> 1 | B7: =R7 -> Board_GX | C7: L2-BOX | D7: =$D$4 -> BOX_CAM | E7: =$J$2 -> 0 | F7: =$J$3 -> BOM_CameraBox_2026-04-14 2205 | G7: Board_GX | H7: Module | I7: Board_GX | M7: pcs | N7: 1 | O7: =$J$4 -> 500 | P7: =IF($N7="","",$N7*$O7) -> 500 | Q7: MKP | R7: Board_GX | U7: Approved | V7: No Substitute | W7: Important / High | X7: Released | Y7: Do Not Buy | AG7: 0 | AJ7: =P7-SUM(AG7:AI7) -> 500
A8: =ROW()-6 -> 2 | B8: =R8 -> Board_RK3562 | C8: L2-BOX | D8: =$D$4 -> BOX_CAM | E8: =$J$2 -> 0 | F8: =$J$3 -> BOM_CameraBox_2026-04-14 2205 | G8: Board_RK3562 | H8: Module | I8: Board_RK3562 | M8: pcs | N8: 1 | O8: =$J$4 -> 500 | P8: =IF($N8="","",$N8*$O8) -> 500 | Q8: MKP | R8: Board_RK3562 | U8: Approved | V8: No Substitute | W8: Important / High | X8: Released | Y8: Do Not Buy | AG8: 0 | AJ8: =P8-SUM(AG8:AI8) -> 500
A9: =ROW()-6 -> 3 | B9: =R9 -> AHGG.101 | C9: L2-BOX | D9: =$D$4 -> BOX_CAM | E9: =$J$2 -> 0 | F9: =$J$3 -> BOM_CameraBox_2026-04-14 2205 | H9: Antenna | I9: AHGG.101 Ăng Ten GPS/BD Box Đầu SMA Đực Dây Dài 2m | M9: pcs | N9: 0 | O9: =$J$4 -> 500 | P9: =IF($N9="","",$N9*$O9) -> 0 | Q9: TGIC | R9: AHGG.101 | U9: Approved | V9: Approval Required | W9: Normal / Low | X9: Released | Y9: XFEMS Buy | AC9: SL giảm từ 1 về 0 do chỉ lắp nguyên BOX_CAM | AE9: 500 | AF9: =P9 -> 0 | AG9: 0 | AJ9: =P9-SUM(AG9:AI9) -> 0
A10: =ROW()-6 -> 4 | B10: =R10 -> AH3G.403 | C10: L2-BOX | D10: =$D$4 -> BOX_CAM | E10: =$J$2 -> 0 | F10: =$J$3 -> BOM_CameraBox_2026-04-14 2205 | H10: Antenna | I10: AH3G.403 Ăng Ten 2G/3G/4G Đầu SMA Đực Dây Dài 2m | M10: pcs | N10: 0 | O10: =$J$4 -> 500 | P10: =IF($N10="","",$N10*$O10) -> 0 | Q10: TGIC | R10: AH3G.403 | U10: Approved | V10: Approval Required | W10: Normal / Low | X10: Released | Y10: XFEMS Buy | AC10: SL giảm từ 1 về 0 do chỉ lắp nguyên BOX_CAM | AE10: 500 | AF10: =P10 -> 0 | AG10: 0 | AJ10: =P10-SUM(AG10:AI10) -> 0
A11: =ROW()-6 -> 5 | B11: =R11 -> TannhietSOM | C11: L2-BOX | D11: =$D$4 -> BOX_CAM | E11: =$J$2 -> 0 | F11: =$J$3 -> BOM_CameraBox_2026-04-14 2205 | H11: Heat sink | I11: tản nhiệt SOM 62x62x15mm | M11: pcs | N11: 1 | O11: =$J$4 -> 500 | P11: =IF($N11="","",$N11*$O11) -> 500 | Q11: Promise | R11: TannhietSOM | U11: Approved | V11: No Substitute | W11: Normal / Low | X11: Released | Y11: XFEMS Buy | AC11: MKP tự thiết kế đặt mua, chưa tiết lộ nguồn cung cấp | AE11: 500 | AF11: =P11-AE11 -> 0 | AG11: 0 | AH11: =VLOOKUP(B11,'VNET-XF_dự kiến lần 2'!$B$2:$D$42,3,0) -> 500 | AJ11: =P11-SUM(AG11:AI11) -> 0
A12: =ROW()-6 -> 6 | B12: =R12 -> CR2016 | C12: L2-BOX | D12: =$D$4 -> BOX_CAM | E12: =$J$2 -> 0 | F12: =$J$3 -> BOM_CameraBox_2026-04-14 2205 | H12: Battery | I12: Pin CR2016 | M12: pcs | N12: 1 | O12: =$J$4 -> 500 | P12: =IF($N12="","",$N12*$O12) -> 500 | Q12: Aliexpress | R12: CR2016 | S12: Linh kiện điện tử SMD | T12: CR2016 | U12: Approved | V12: Approval Required | W12: Normal / Low | X12: Released | Y12: XFEMS Buy | AE12: 0 | AF12: =P12-AE12 -> 500 | AG12: 0 | AH12: =VLOOKUP(B12,'VNET-XF_dự kiến lần 2'!$B$2:$D$42,3,0) -> 500 | AJ12: =P12-SUM(AG12:AI12) -> 0
A13: =ROW()-6 -> 7 | B13: =R13 -> 200mAh 3.7V | C13: L2-BOX | D13: =$D$4 -> BOX_CAM | E13: =$J$2 -> 0 | F13: =$J$3 -> BOM_CameraBox_2026-04-14 2205 | H13: Battery | I13: 402030 200mAh 3.7V Lithium Polymer Battery for Smart Bracelet Voice Recorder GPS Tablet PC Pet Training Tool Webcam Cell | M13: pcs | N13: 1 | O13: =$J$4 -> 500 | P13: =IF($N13="","",$N13*$O13) -> 500 | Q13: Aliexpress | R13: 200mAh 3.7V | U13: Approved | V13: Approval Required | W13: Normal / Low | X13: Released | Y13: XFEMS Buy | AA13: Aliexpress | AC13: Thêm mới do prototype không mua | AD13: link | AE13: 0 | AF13: =P13 -> 500 | AG13: 0 | AJ13: =P13-SUM(AG13:AI13) -> 500
A14: =ROW()-6 -> 8 | B14: =R14 -> KDT-2526 | C14: L2-BOX | D14: =$D$4 -> BOX_CAM | E14: =$J$2 -> 0 | F14: =$J$3 -> BOM_CameraBox_2026-04-14 2205 | H14: Others | I14: Vỏ hộp | M14: pcs | N14: 1 | O14: =$J$4 -> 500 | P14: =IF($N14="","",$N14*$O14) -> 500 | Q14: Aliexpress | R14: KDT-2526 | U14: Approved | V14: No Substitute | W14: Important / High | X14: Released | Y14: XFEMS Buy | AA14: Aliexpress | AE14: 500 | AF14: =P14-AE14 -> 0 | AG14: 0 | AJ14: =P14-SUM(AG14:AI14) -> 500
A15: =ROW()-6 -> 9 | B15: =R15 -> 1.13Ipex | C15: L2-BOX | D15: =$D$4 -> BOX_CAM | E15: =$J$2 -> 0 | F15: =$J$3 -> BOM_CameraBox_2026-04-14 2205 | H15: Connector | I15: Cáp RF Đầu SMA Cái Nối 1.13Ipex Dài 10cm | M15: pcs | N15: 2 | O15: =$J$4 -> 500 | P15: =IF($N15="","",$N15*$O15) -> 1000 | Q15: Aliexpress | R15: 1.13Ipex | U15: Approved | V15: Approval Required | W15: Normal / Low | X15: Released | Y15: XFEMS Buy | AA15: Aliexpress | AD15: link | AE15: 0 | AF15: =P15-AE15 -> 1000 | AG15: 0 | AJ15: =P15-SUM(AG15:AI15) -> 1000
A16: =ROW()-6 -> 10 | B16: =R16 -> Heatsink 8.8 x 8.8 x 12mm | C16: L2-BOX | D16: =$D$4 -> BOX_CAM | E16: =$J$2 -> 0 | F16: =$J$3 -> BOM_CameraBox_2026-04-14 2205 | H16: Heatsink | I16: Heatsink 8.8 x 8.8 x 12mm Adhesive backing – peel-and-stick thermal tape. Black Color | M16: pcs | N16: 1 | O16: =$J$4 -> 500 | P16: =IF($N16="","",$N16*$O16) -> 500 | Q16: China / GEMAY | R16: Heatsink 8.8 x 8.8 x 12mm | U16: Approved | V16: Approval Required | W16: Normal / Low | X16: Released | Y16: XFEMS Buy | AA16: Aliexpress | AB16: Đã mua bổ sung 500 ở đợt 1 | AC16: Sửa lại mô tả: Heatsink 8.8 x 8.8 x 12mm Adhesive backing – peel-and-stick thermal tape. Black Color | AD16: link | AE16: 0 | AF16: =P16-AE16 -> 500 | AG16: 0 | AI16: 500 | AJ16: =P16-SUM(AG16:AI16) -> 0
A17: =ROW()-6 -> 11 | B17: =R17 -> 100x100x2mm | C17: L2-BOX | D17: =$D$4 -> BOX_CAM | E17: =$J$2 -> 0 | F17: =$J$3 -> BOM_CameraBox_2026-04-14 2205 | H17: Others | I17: Miếng dẫn nhiệt thermal pad 5W/mK cho vga, chipset, ic dày 0.5, 1, 1.5, 2, 2.5, 3, 5mm .kienstore358 | M17: pcs | N17: 0.1 | O17: =$J$4 -> 500 | P17: =IF($N17="","",$N17*$O17) -> 50 | Q17: Aliexpress | R17: 100x100x2mm | U17: Approved | V17: Approval Required | W17: Normal / Low | X17: Released | Y17: XFEMS Buy | AA17: Aliexpress | AC17: giảm 1 xuống 0.2 do 1 tấm sử dụng được cho 10-15 mạch | AD17: link | AE17: 0 | AF17: =P17-AE17 -> 50 | AG17: 0 | AJ17: =P17-SUM(AG17:AI17) -> 50
A18: =ROW()-6 -> 12 | B18: =R18 -> SYD2510HSL | C18: L2-BOX | D18: =$D$4 -> BOX_CAM | E18: =$J$2 -> 0 | F18: =$J$3 -> BOM_CameraBox_2026-04-14 2205 | H18: Fan | I18: Quạt làm mát Mini EIbbkg 12V 25mm 2510 25x25x10mm 2 chân DC Nhỏ Micro Cooler 2 gói mới | M18: pcs | N18: 1 | O18: =$J$4 -> 500 | P18: =IF($N18="","",$N18*$O18) -> 500 | Q18: SHENGYIDA | R18: SYD2510HSL | U18: Not Yet Approved | V18: Approval Required | W18: Normal / Low | X18: Released | Y18: XFEMS Buy | AA18: VNES | AB18: Đã mua bổ sung 500 ở đợt 1 | AC18: Sửa lại mô tả, đây là quạt 5V: "5V Ball/Sleeve Axial Cooler Hydraulic Bearing 25x25x10mm Mini Cooling Fan 2510 25mm Centrifugal Electric 3D Printer Fan Cable length: >50mm with XH2.5mm connector" | AD18: link | AE18: 0 | AF18: =P18 -> 500 | AG18: 0 | AI18: 500 | AJ18: =P18-SUM(AG18:AI18) -> 0
A19: =ROW()-6 -> 13 | B19: Lò Xo Kẹp 17.6mm | C19: L2-BOX | D19: =$D$4 -> BOX_CAM | E19: =$J$2 -> 0 | F19: =$J$3 -> BOM_CameraBox_2026-04-14 2205 | H19: Others | I19: 17.6mm Plastic Nail Southbridge Northbridge Cooling Fan Plastic Spring Clips Secure Mounting | M19: pcs | N19: 2 | O19: =$J$4 -> 500 | P19: =IF($N19="","",$N19*$O19) -> 1000 | Q19: China / GEMAY | R19: Lò Xo Kẹp 17.6mm | U19: Approved | V19: Approval Required | W19: Normal / Low | X19: Released | Y19: XFEMS Buy | AA19: VNES | AB19: Đã mua bổ sung 1000 ở đợt 1 | AD19: link | AE19: 0 | AF19: =P19-AE19 -> 1000 | AG19: 0 | AH19: =VLOOKUP(B19,'VNET-XF_dự kiến lần 2'!$B$2:$D$42,3,0) -> 1000 | AI19: 1000 | AJ19: =P19-SUM(AG19:AI19) -> -1000
A20: =ROW()-6 -> 14 | B20: =R20 -> M3x16mm | C20: L2-BOX | D20: =$D$4 -> BOX_CAM | E20: =$J$2 -> 0 | F20: =$J$3 -> BOM_CameraBox_2026-04-14 2205 | H20: Others | I20: 10 cái M3 M4 M5 Bulong lục giác chìm đầu bằng đen thép mạ cấp bền 10.9 M3 M4 M5 | M20: pcs | N20: 4 | O20: =$J$4 -> 500 | P20: =IF($N20="","",$N20*$O20) -> 2000 | Q20: Aliexpress | R20: M3x16mm | U20: Approved | V20: Approval Required | W20: Normal / Low | X20: Released | Y20: XFEMS Buy | AA20: Aliexpress | AC20: Vít cho quạt | AD20: link | AE20: 0 | AF20: =P20-AE20 -> 2000 | AG20: 0 | AH20: =VLOOKUP(B20,'VNET-XF_dự kiến lần 2'!$B$2:$D$42,3,0) -> 2000 | AJ20: =P20-SUM(AG20:AI20) -> 0
A21: =ROW()-6 -> 15 | B21: =R21 -> M3 Inox304 | C21: L2-BOX | D21: =$D$4 -> BOX_CAM | E21: =$J$2 -> 0 | F21: =$J$3 -> BOM_CameraBox_2026-04-14 2205 | H21: Others | I21: Set 50, 20 Tán Dẹp Ecu Inox 304, thép thôi, thép mạ Cho ốc M3, M4, M5, M6, M8 Set 10 con đai ốc inox loại tốt | M21: pcs | N21: 4 | O21: =$J$4 -> 500 | P21: =IF($N21="","",$N21*$O21) -> 2000 | Q21: Aliexpress | R21: M3 Inox304 | U21: Approved | V21: Approval Required | W21: Normal / Low | X21: Released | Y21: XFEMS Buy | AA21: Aliexpress | AC21: Bulong hàn cho quạt | AD21: link | AE21: 0 | AF21: =P21-AE21 -> 2000 | AG21: 0 | AH21: =VLOOKUP(B21,'VNET-XF_dự kiến lần 2'!$B$2:$D$42,3,0) -> 2000 | AJ21: =P21-SUM(AG21:AI21) -> 0
A22: =ROW()-6 -> 16 | B22: =R22 -> M2x4mm | C22: L2-BOX | D22: =$D$4 -> BOX_CAM | E22: =$J$2 -> 0 | F22: =$J$3 -> BOM_CameraBox_2026-04-14 2205 | H22: Others | I22: Ốc vít Máy tính Laptop PC ổ cứng SSD HDD Main fan Linh kiện | M2 M2x3 M2.5x5 M3x5 M3.5x6 M4 M5 | M22: pcs | N22: 1 | O22: =$J$4 -> 500 | P22: =IF($N22="","",$N22*$O22) -> 500 | Q22: Aliexpress | R22: M2x4mm | U22: Approved | V22: Approval Required | W22: Normal / Low | X22: Released | Y22: XFEMS Buy | AA22: Aliexpress | AC22: Vít M2 SSD | AD22: link | AE22: 0 | AF22: =P22-AE22 -> 500 | AG22: 0 | AH22: =VLOOKUP(B22,'VNET-XF_dự kiến lần 2'!$B$2:$D$42,3,0) -> 500 | AJ22: =P22-SUM(AG22:AI22) -> 0
A23: =ROW()-6 -> 17 | B23: =R23 -> M3 | C23: L2-BOX | D23: =$D$4 -> BOX_CAM | E23: =$J$2 -> 0 | F23: =$J$3 -> BOM_CameraBox_2026-04-14 2205 | H23: Others | I23: Set 50, 20 cái long đền vênh vòng đệm vênh ốc M2 M3 M4 M5 M6 các loại | M23: pcs | N23: 4 | O23: =$J$4 -> 500 | P23: =IF($N23="","",$N23*$O23) -> 2000 | Q23: Aliexpress | R23: M3 | U23: Approved | V23: Approval Required | W23: Normal / Low | X23: Released | Y23: XFEMS Buy | AA23: Aliexpress | AC23: Vênh cho quạt | AD23: link | AE23: 0 | AF23: =P23-AE23 -> 2000 | AG23: 0 | AH23: =VLOOKUP(B23,'VNET-XF_dự kiến lần 2'!$B$2:$D$42,3,0) -> 2000 | AJ23: =P23-SUM(AG23:AI23) -> 0
A24: =ROW()-6 -> 18 | B24: =R24 -> MAV-WH161 | C24: L2-BOX | D24: =$D$4 -> BOX_CAM | E24: =$J$2 -> 0 | F24: =$J$3 -> BOM_CameraBox_2026-04-14 2205 | H24: Cable/Harness | I24: Dây điện connector 4P | M24: m | N24: 0 | O24: =$J$4 -> 500 | P24: =IF($N24="","",$N24*$O24) -> 0 | Q24: Aliexpress | R24: MAV-WH161 | U24: Not Yet Approved | V24: Approval Required | W24: Normal / Low | X24: Released | Y24: XFEMS Buy | AA24: Aliexpress | AC24: SL giảm từ 1 về 0 do chỉ lắp nguyên BOX_CAM | AE24: 0 | AF24: =P24-AE24 -> 0 | AG24: 0 | AJ24: =P24-SUM(AG24:AI24) -> 0
A25: =ROW()-6 -> 19 | B25: =R25 -> L2464-24AWG-4C | C25: L2-BOX | D25: =$D$4 -> BOX_CAM | E25: =$J$2 -> 0 | F25: =$J$3 -> BOM_CameraBox_2026-04-14 2205 | H25: Cable/Harness | I25: Dây Cáp Nhôm 4 Lõi UL2464-24AWG-4C 4x0.2mm2 Vỏ PVC | M25: m | N25: 0 | O25: =$J$4 -> 500 | P25: =IF($N25="","",$N25*$O25) -> 0 | Q25: Aliexpress | R25: L2464-24AWG-4C | U25: Not Yet Approved | V25: Approval Required | W25: Normal / Low | X25: Released | Y25: XFEMS Buy | AA25: Aliexpress | AC25: SL giảm từ 1 về 0 do chỉ lắp nguyên BOX_CAM | AE25: 3050 | AF25: =P25-AE25 -> -3050 | AG25: 0 | AJ25: =P25-SUM(AG25:AI25) -> 0
A26: =ROW()-6 -> 20 | B26: =R26 -> GX12-2P (Cái) | C26: L2-BOX | D26: =$D$4 -> BOX_CAM | E26: =$J$2 -> 0 | F26: =$J$3 -> BOM_CameraBox_2026-04-14 2205 | H26: Connector | I26: Giắc GX12-2P 2 Chân (Cái) Đấu Dây | M26: pcs | N26: 0 | O26: =$J$4 -> 500 | P26: =IF($N26="","",$N26*$O26) -> 0 | Q26: Aliexpress | R26: GX12-2P (Cái) | U26: Not Yet Approved | V26: Approval Required | W26: Normal / Low | X26: Released | Y26: XFEMS Buy | AA26: Aliexpress | AC26: SL giảm từ 1 về 0 do chỉ lắp nguyên BOX_CAM | AD26: link | AE26: 0 | AF26: =P26-AE26 -> 0 | AG26: 0 | AH26: =VLOOKUP(B26,'VNET-XF_dự kiến lần 2'!$B$2:$D$42,3,0) -> 500 | AJ26: =P26-SUM(AG26:AI26) -> -500
A27: =ROW()-6 -> 21 | B27: =R27 -> Dow Corning 3140 RTV | C27: L2-BOX | D27: =$D$4 -> BOX_CAM | E27: =$J$2 -> 0 | F27: =$J$3 -> BOM_CameraBox_2026-04-14 2205 | H27: Others | I27: Keo silicone cố định linh kiện | M27: pcs | N27: 0.1 | O27: =$J$4 -> 500 | P27: =IF($N27="","",$N27*$O27) -> 50 | Q27: DOW | R27: Dow Corning 3140 RTV | U27: Not Yet Approved | V27: Approval Required | W27: Normal / Low | X27: Released | Y27: XFEMS Buy | AA27: Aliexpress | AC27: Thêm mới để cố định linh kiện mạch, 1 lọ 90ml cho 10-20 mạch | AE27: 0 | AF27: =P27 -> 50 | AG27: 0 | AJ27: =P27-SUM(AG27:AI27) -> 50

Sheet Board RK3562
A1: XFORCE EMS - ENGINEERING BOM RELEASE TEMPLATE
A2: Project Name | D2: CAMBOX V4- RK3562 | I2: PCB Rev | J2: Gerber_CAMBOX_RK3562_lot500_2505 | N2: Dessigned By | Q2: Đỗ Việt Đức | U2: Customer | W2: VNET
A3: Product Name | D3: CAMBOX V4- RK3562 | I3: BOM Rev | J3: BOM_CameraBox_2026-04-14 2205 | N3: Approved By | Q3: Cấn Văn Lịch | U3: Modified Date
A4: Board Name | D4: Board RK3562 | I4: Lot Qty | J4: 500 | N4: Date Created | Q4: 46168 | U4: Change Ref / ECN No.
B5: 6 | C5: select | D5: fcn | E5: fcn | F5: fcn | G5: must fill | H5: select | I5: must fill | J5: must fill | K5: select | L5: select | N5: must fill | O5: fcn | P5: fcn | Q5: must fill | R5: must fill | S5: must fill | T5: must fill | U5: select | V5: select | W5: select | X5: select | Y5: select | AA5: must fill | AG5: Lịch CV rà soát
A6: No | B6: PivotCol | C6: BOM Level | D6: Board Name | E6: PCB Rev | F6: BOM Rev | G6: RefDes | H6: Category | I6: Description | J6: Package / Footprint | K6: Mounting type | L6: Mount Status' | M6: Unit | N6: Qty/Set | O6: Board Qty | P6: Total Engineer Qty | Q6: Manufacturer 1 | R6: PN1 | S6: Manufacturer 2 | T6: PN2 | U6: AVL Status | V6: Substitution Rule | W6: Critical Level | X6: Release Status | Y6: Supply Type | Z6: Internal Code | AA6: Ref Supplier | AB6: Engineer Note | AC6: Change Note | AD6: Ref Link / Datasheet | AE6: SL đã có trong kho chị HÀ | AF6: SL cần mua | AG6: SL VNET Đã Bàn Giao CHO XFORCE | AH6: SL VNET dự kiến Bàn giao lần 2 | AI6: SL XF EMS đã mua bổ sung đợt 1 | AJ6: SL cần mua bổ sung đợt 2
A7: =ROW()-6 -> 1 | B7: =R7 -> XS9922B | C7: L1-PCBA | D7: =$D$4 -> Board RK3562 | E7: =$J$2 -> Gerber_CAMBOX_RK3562_lot500_2505 | F7: =$J$3 -> BOM_CameraBox_2026-04-14 2205 | G7: U6 | H7: IC | I7: 4Ch HD/SD Analog Video Decoder | K7: SMD | L7: Mounted | M7: pcs | N7: 1 | O7: =$J$4 -> 500 | P7: =IF($N7="","",$N7*$O7) -> 500 | Q7: CHIPUP | R7: XS9922B | U7: Approved | V7: No Substitute | W7: Important / High | X7: Released | Y7: XFEMS Buy | AA7: CHIPUP | AE7: =VLOOKUP(R7,'[1]VNSH03 gia thanh sx '!$F$6:$G$171,2,0) -> 500 | AF7: =P7-AE7 -> 0 | AG7: =IF(VLOOKUP(R7,'VNET-XF-2105'!$B$12:$D$145,3,0)>=P7,P7,VLOOKUP(R7,'VNET-XF-2105'!$B$12:$D$145,3,0)) -> 489 | AJ7: =P7-SUM(AG7:AI7) -> 11
A8: =ROW()-6 -> 2 | B8: =R8 -> TannhietSOM | C8: L1-PCBA | D8: =$D$4 -> Board RK3562 | E8: =$J$2 -> Gerber_CAMBOX_RK3562_lot500_2505 | F8: =$J$3 -> BOM_CameraBox_2026-04-14 2205 | G8: H1 | H8: Heatsink | I8: 62x62x15mm | K8: TH | L8: Mounted | M8: pcs | N8: 1 | O8: =$J$4 -> 500 | P8: =IF($N8="","",$N8*$O8) -> 500 | Q8: Promise | R8: TannhietSOM | U8: Approved | V8: Approval Required | W8: Normal / Low | X8: Released | Y8: XFEMS Buy | AA8: LCSC | AC8: SL giảm về 0 do chuyển sang BOX_CAM | AE8: =VLOOKUP(R8,'[1]VNSH03 gia thanh sx '!$F$6:$G$171,2,0) -> 500 | AF8: =P8-AE8 -> 0 | AH8: =IF(VLOOKUP(R8,'VNET-XF_dự kiến lần 2'!$B$2:$D$42,3,0)>=(P8-AG8),(P8-AG8),VLOOKUP(R8,'VNET-XF_dự kiến lần 2'!$B$2:$D$42,3,0)) -> 500 | AJ8: =P8-SUM(AG8:AI8) -> 0
A9: =ROW()-6 -> 3 | B9: =R9 -> RK3562 | C9: L1-PCBA | D9: =$D$4 -> Board RK3562 | E9: =$J$2 -> Gerber_CAMBOX_RK3562_lot500_2505 | F9: =$J$3 -> BOM_CameraBox_2026-04-14 2205 | G9: M1 | H9: IC | I9: RK3562 SOM - System on Module | K9: SMD | L9: Mounted | M9: pcs | N9: 1 | O9: =$J$4 -> 500 | P9: =IF($N9="","",$N9*$O9) -> 500 | Q9: RONGPIN | R9: RK3562 | U9: Approved | V9: No Substitute | W9: Important / High | X9: Released | Y9: XFEMS Buy | AA9: RONGPIN | AE9: =VLOOKUP(R9,'[1]VNSH03 gia thanh sx '!$F$6:$G$171,2,0) -> 500 | AF9: =P9-AE9 -> 0 | AG9: =IF(VLOOKUP(R9,'VNET-XF-2105'!$B$12:$D$145,3,0)>=P9,P9,VLOOKUP(R9,'VNET-XF-2105'!$B$12:$D$145,3,0)) -> 488 | AJ9: =P9-SUM(AG9:AI9) -> 12
A10: =ROW()-6 -> 4 | B10: =R10 -> RVT1C471M0810 | C10: L1-PCBA | D10: =$D$4 -> Board RK3562 | E10: =$J$2 -> Gerber_CAMBOX_RK3562_lot500_2505 | F10: =$J$3 -> BOM_CameraBox_2026-04-14 2205 | G10: C13 | H10: Capacitor | I10: 470uF ±20% 16V Aluminum Electrolytic Capacitors 2000hrs@105℃ | K10: SMD | L10: Mounted | M10: pcs | N10: 1 | O10: =$J$4 -> 500 | P10: =IF($N10="","",$N10*$O10) -> 500 | Q10: ROQANG | R10: RVT1C471M0810 | U10: Approved | V10: Approval Required | W10: Normal / Low | X10: Released | Y10: XFEMS Buy | AA10: LCSC | AC10: SL thêm 1: C13 từ 100uF sang 470 uF | AE10: =VLOOKUP(R10,'[1]VNSH03 gia thanh sx '!$F$6:$G$171,2,0) -> 500 | AF10: =P10-AE10 -> 0 | AJ10: =P10-SUM(AG10:AI10) -> 500
A11: =ROW()-6 -> 5 | B11: =R11 -> C0603X5R105K500NT | C11: L1-PCBA | D11: =$D$4 -> Board RK3562 | E11: =$J$2 -> Gerber_CAMBOX_RK3562_lot500_2505 | F11: =$J$3 -> BOM_CameraBox_2026-04-14 2205 | G11: C1, C15, C49, C57, C59, C139 | H11: Capacitor | I11: CAP CER 1UF 50V X5R 0603 | J11: 0603 | K11: SMD | L11: Mounted | M11: pcs | N11: 6 | O11: =$J$4 -> 500 | P11: =IF($N11="","",$N11*$O11) -> 3000 | Q11: Hottech | R11: C0603X5R105K500NT | U11: Approved | V11: Approval Required | W11: Normal / Low | X11: Released | Y11: XFEMS Buy | AA11: LCSC | AC11: SL giảm từ 7 còn 6 do C48 DNP | AE11: =VLOOKUP(R11,'[1]VNSH03 gia thanh sx '!$F$6:$G$171,2,0) -> 2500 | AF11: =P11-AE11 -> 500 | AH11: =IF(VLOOKUP(R11,'VNET-XF_dự kiến lần 2'!$B$2:$D$42,3,0)>=(P11-AG11),(P11-AG11),VLOOKUP(R11,'VNET-XF_dự kiến lần 2'!$B$2:$D$42,3,0)) -> 3000 | AJ11: =P11-SUM(AG11:AI11) -> 0
A12: =ROW()-6 -> 6 | B12: =R12 -> CC1206KKX7R0BB104 | C12: L1-PCBA | D12: =$D$4 -> Board RK3562 | E12: =$J$2 -> Gerber_CAMBOX_RK3562_lot500_2505 | F12: =$J$3 -> BOM_CameraBox_2026-04-14 2205 | G12: C2, C19 | H12: Capacitor | I12: 100V 100nF X7R ±10% 1206 Multilayer Ceramic Capacitors MLCC - SMD/SMT ROHS | J12: 1206 | K12: SMD | L12: Mounted | M12: pcs | N12: 2 | O12: =$J$4 -> 500 | P12: =IF($N12="","",$N12*$O12) -> 1000 | Q12: Yageo | R12: CC1206KKX7R0BB104 | U12: Approved | V12: Approval Required | W12: Normal / Low | X12: Released | Y12: XFEMS Buy | AA12: LCSC | AE12: =VLOOKUP(R12,'[1]VNSH03 gia thanh sx '!$F$6:$G$171,2,0) -> 1000 | AF12: =P12-AE12 -> 0 | AG12: =IF(VLOOKUP(R12,'VNET-XF-2105'!$B$12:$D$145,3,0)>=P12,P12,VLOOKUP(R12,'VNET-XF-2105'!$B$12:$D$145,3,0)) -> 990 | AJ12: =P12-SUM(AG12:AI12) -> 10
A13: =ROW()-6 -> 7 | B13: =R13 -> RVT2A100M0605 | C13: L1-PCBA | D13: =$D$4 -> Board RK3562 | E13: =$J$2 -> Gerber_CAMBOX_RK3562_lot500_2505 | F13: =$J$3 -> BOM_CameraBox_2026-04-14 2205 | G13: C3, C21 | H13: Capacitor | I13: 10uF 100V 63mA@120Hz ±20% SMD,D6.3xL5.4mm Aluminum Electrolytic Capacitors - SMD ROHS | K13: SMD | L13: Mounted | M13: pcs | N13: 2 | O13: =$J$4 -> 500 | P13: =IF($N13="","",$N13*$O13) -> 1000 | Q13: ROQANG | R13: RVT2A100M0605 | U13: Approved | V13: Approval Required | W13: Normal / Low | X13: Released | Y13: XFEMS Buy | AA13: LCSC | AE13: =VLOOKUP(R13,'[1]VNSH03 gia thanh sx '!$F$6:$G$171,2,0) -> 1000 | AF13: =P13-AE13 -> 0 | AG13: =IF(VLOOKUP(R13,'VNET-XF-2105'!$B$12:$D$145,3,0)>=P13,P13,VLOOKUP(R13,'VNET-XF-2105'!$B$12:$D$145,3,0)) -> 990 | AJ13: =P13-SUM(AG13:AI13) -> 10
A14: =ROW()-6 -> 8 | B14: =R14 -> CS3225X7R106K500NRL | C14: L1-PCBA | D14: =$D$4 -> Board RK3562 | E14: =$J$2 -> Gerber_CAMBOX_RK3562_lot500_2505 | F14: =$J$3 -> BOM_CameraBox_2026-04-14 2205 | G14: C4, C7, C10, C16, C18 | H14: Capacitor | I14: 10uF 50V Ceramic Capacitor X7R 1210 | J14: 1210 | K14: SMD | L14: Mounted | M14: pcs | N14: 5 | O14: =$J$4 -> 500 | P14: =IF($N14="","",$N14*$O14) -> 2500 | Q14: SAMWHA | R14: CS3225X7R106K500NRL | U14: Approved | V14: Approval Required | W14: Normal / Low | X14: Released | Y14: XFEMS Buy | AA14: LCSC | AE14: =VLOOKUP(R14,'[1]VNSH03 gia thanh sx '!$F$6:$G$171,2,0) -> 3500 | AF14: =P14-AE14 -> -1000 | AG14: =IF(VLOOKUP(R14,'VNET-XF-2105'!$B$12:$D$145,3,0)>=P14,P14,VLOOKUP(R14,'VNET-XF-2105'!$B$12:$D$145,3,0)) -> 2475 | AJ14: =P14-SUM(AG14:AI14) -> 25
A15: =ROW()-6 -> 9 | B15: =R15 -> CC0603KRX7R9BB104 | C15: L1-PCBA | D15: =$D$4 -> Board RK3562 | E15: =$J$2 -> Gerber_CAMBOX_RK3562_lot500_2505 | F15: =$J$3 -> BOM_CameraBox_2026-04-14 2205 | G15: C5, C8, C9, C22, C25, C35, C37, C106, C156, C158, C193,C198 | H15: Capacitor | I15: 50V 100nF X7R ±10% 0603 Multilayer Ceramic Capacitors MLCC - SMD/SMT ROHS | J15: 0603 | K15: SMD | L15: Mounted | M15: pcs | N15: 12 | O15: =$J$4 -> 500 | P15: =IF($N15="","",$N15*$O15) -> 6000 | Q15: Yageo | R15: CC0603KRX7R9BB104 | U15: Approved | V15: Approval Required | W15: Normal / Low | X15: Released | Y15: XFEMS Buy | AA15: LCSC | AC15: Số lượng 11 lên 12: Thêm C198 | AE15: =VLOOKUP(R15,'[1]VNSH03 gia thanh sx '!$F$6:$G$171,2,0) -> 6500 | AF15: =P15-AE15 -> -500 | AG15: =IF(VLOOKUP(R15,'VNET-XF-2105'!$B$12:$D$145,3,0)>=P15,P15,VLOOKUP(R15,'VNET-XF-2105'!$B$12:$D$145,3,0)) -> 5445 | AJ15: =P15-SUM(AG15:AI15) -> 555
A16: =ROW()-6 -> 10 | B16: =R16 -> CC0402JRNPO9BN220 | C16: L1-PCBA | D16: =$D$4 -> Board RK3562 | E16: =$J$2 -> Gerber_CAMBOX_RK3562_lot500_2505 | F16: =$J$3 -> BOM_CameraBox_2026-04-14 2205 | G16: C6, C17 | H16: Capacitor | I16: 22pF ±5% 50V Ceramic Capacitor NP0 0402 | J16: 0402 | K16: SMD | L16: Mounted | M16: pcs | N16: 2 | O16: =$J$4 -> 500 | P16: =IF($N16="","",$N16*$O16) -> 1000 | Q16: Yageo | R16: CC0402JRNPO9BN220 | U16: Approved | V16: Approval Required | W16: Normal / Low | X16: Released | Y16: XFEMS Buy | AA16: LCSC | AE16: =VLOOKUP(R16,'[1]VNSH03 gia thanh sx '!$F$6:$G$171,2,0) -> 1500 | AF16: =P16-AE16 -> -500 | AG16: =IF(VLOOKUP(R16,'VNET-XF-2105'!$B$12:$D$145,3,0)>=P16,P16,VLOOKUP(R16,'VNET-XF-2105'!$B$12:$D$145,3,0)) -> 990 | AJ16: =P16-SUM(AG16:AI16) -> 10
A17: =ROW()-6 -> 11 | B17: =R17 -> FCC0402B681K500AT | C17: L1-PCBA | D17: =$D$4 -> Board RK3562 | E17: =$J$2 -> Gerber_CAMBOX_RK3562_lot500_2505 | F17: =$J$3 -> BOM_CameraBox_2026-04-14 2205 | G17: C11 | H17: Capacitor | I17: 680pF ±10% 50V Ceramic Capacitor X7R 0402 | J17: 0402 | K17: SMD | L17: Mounted | M17: pcs | N17: 1 | O17: =$J$4 -> 500 | P17: =IF($N17="","",$N17*$O17) -> 500 | Q17: FOJAN | R17: FCC0402B681K500AT | U17: Approved | V17: Approval Required | W17: Normal / Low | X17: Released | Y17: XFEMS Buy | AA17: LCSC | AE17: =VLOOKUP(R17,'[1]VNSH03 gia thanh sx '!$F$6:$G$171,2,0) -> 500 | AF17: =P17-AE17 -> 0 | AG17: =IF(VLOOKUP(R17,'VNET-XF-2105'!$B$12:$D$145,3,0)>=P17,P17,VLOOKUP(R17,'VNET-XF-2105'!$B$12:$D$145,3,0)) -> 495 | AJ17: =P17-SUM(AG17:AI17) -> 5
A18: =ROW()-6 -> 12 | B18: =R18 -> CC0402KRX7R7BB104 | C18: L1-PCBA | D18: =$D$4 -> Board RK3562 | E18: =$J$2 -> Gerber_CAMBOX_RK3562_lot500_2505 | F18: =$J$3 -> BOM_CameraBox_2026-04-14 2205 | G18: C12, C32, C39, C42, C43, C50, C51, C52, C54, C56, C58, C60, C61, C62, C63, C64, C65, C66, C67, C68, C69, C72, C73, C74, C75, C76, C77, C78, C79, C80, C82, C84, C86, C87, C88, C89, C91, C93, C94, C96, C97, C98, C99, C100, C102, C103, C108, C111, C113, C116, C118, C119, C120, C121, C124, C125, C126, C127, C128, C129, C130, C131, C132, C135, C137, C144, C145, C148, C160, C166, C167, C169, C171, C172, C173, C175, C178, C181, C182, C183, C184, C186, C189, C191, C192 | H18: Capacitor | I18: 16V 100nF X7R ±10% 0402 Multilayer Ceramic Capacitors MLCC - SMD/SMT ROHS | J18: 0402 | K18: SMD | L18: Mounted | M18: pcs | N18: 83 | O18: =$J$4 -> 500 | P18: =IF($N18="","",$N18*$O18) -> 41500 | Q18: Yageo | R18: CC0402KRX7R7BB104 | U18: Approved | V18: Approval Required | W18: Normal / Low | X18: Released | Y18: XFEMS Buy | AA18: LCSC | AC18: số lượng 86 giảm còn 83: C33, C144,C145 DNP | AE18: =VLOOKUP(R18,'[1]VNSH03 gia thanh sx '!$F$6:$G$171,2,0) -> 41000 | AF18: =P18-AE18 -> 500 | AG18: =IF(VLOOKUP(R18,'VNET-XF-2105'!$B$12:$D$145,3,0)>=P18,P18,VLOOKUP(R18,'VNET-XF-2105'!$B$12:$D$145,3,0)) -> 40570 | AH18: =IF(VLOOKUP(R18,'VNET-XF_dự kiến lần 2'!$B$2:$D$42,3,0)>=(P18-AG18),(P18-AG18),VLOOKUP(R18,'VNET-XF_dự kiến lần 2'!$B$2:$D$42,3,0)) -> 930 | AJ18: =P18-SUM(AG18:AI18) -> 0
A19: =ROW()-6 -> 13 | B19: =R19 -> RT1H101M0810 | C19: L1-PCBA | D19: =$D$4 -> Board RK3562 | E19: =$J$2 -> Gerber_CAMBOX_RK3562_lot500_2505 | F19: =$J$3 -> BOM_CameraBox_2026-04-14 2205 | G19: C45 | H19: Capacitor | I19: 100uF 50V 146mA@120Hz ±20% SMD,D8xL10.2mm Aluminum Electrolytic Capacitors - SMD ROHS | K19: SMD | L19: Mounted | M19: pcs | N19: 1 | O19: =$J$4 -> 500 | P19: =IF($N19="","",$N19*$O19) -> 500 | Q19: ROQANG | R19: RT1H101M0810 | U19: Approved | V19: Approval Required | W19: Normal / Low | X19: Released | Y19: XFEMS Buy | AA19: LCSC | AC19: SL giảm từ 2 xuống 1: C13 chuyển sang dòng 470uF | AE19: =VLOOKUP(R19,'[1]VNSH03 gia thanh sx '!$F$6:$G$171,2,0) -> 1000 | AF19: =P19-AE19 -> -500 | AG19: =IF(VLOOKUP(R19,'VNET-XF-2105'!$B$12:$D$145,3,0)>=P19,P19,VLOOKUP(R19,'VNET-XF-2105'!$B$12:$D$145,3,0)) -> 500 | AJ19: =P19-SUM(AG19:AI19) -> 0
A20: =ROW()-6 -> 14 | B20: =R20 -> CC0402KRX7R9BB822 | C20: L1-PCBA | D20: =$D$4 -> Board RK3562 | E20: =$J$2 -> Gerber_CAMBOX_RK3562_lot500_2505 | F20: =$J$3 -> BOM_CameraBox_2026-04-14 2205 | G20: C14 | H20: Capacitor | I20: 8.2nF ±10% 50V Ceramic Capacitor X7R 0402 | J20: 0402 | K20: SMD | L20: Mounted | M20: pcs | N20: 1 | O20: =$J$4 -> 500 | P20: =IF($N20="","",$N20*$O20) -> 500 | Q20: Yageo | R20: CC0402KRX7R9BB822 | U20: Approved | V20: Approval Required | W20: Normal / Low | X20: Released | Y20: XFEMS Buy | AA20: LCSC | AE20: =VLOOKUP(R20,'[1]VNSH03 gia thanh sx '!$F$6:$G$171,2,0) -> 500 | AF20: =P20-AE20 -> 0 | AG20: =IF(VLOOKUP(R20,'VNET-XF-2105'!$B$12:$D$145,3,0)>=P20,P20,VLOOKUP(R20,'VNET-XF-2105'!$B$12:$D$145,3,0)) -> 495 | AJ20: =P20-SUM(AG20:AI20) -> 5
A21: =ROW()-6 -> 15 | B21: =R21 -> RT1E470M0605 | C21: L1-PCBA | D21: =$D$4 -> Board RK3562 | E21: =$J$2 -> Gerber_CAMBOX_RK3562_lot500_2505 | F21: =$J$3 -> BOM_CameraBox_2026-04-14 2205 | G21: C197 | H21: Capacitor | I21: 47uF ±20% 25V Aluminum Electrolytic Capacitors 2000hrs@125℃ | K21: SMD | L21: Mounted | M21: pcs | N21: 1 | O21: =$J$4 -> 500 | P21: =IF($N21="","",$N21*$O21) -> 500 | Q21: ROQANG | R21: RT1E470M0605 | U21: Approved | V21: Approval Required | W21: Normal / Low | X21: Released | Y21: XFEMS Buy | AA21: LCSC | AC21: Thêm 1 | AE21: =VLOOKUP(R21,'[1]VNSH03 gia thanh sx '!$F$6:$G$171,2,0) -> 500 | AF21: =P21-AE21 -> 0 | AJ21: =P21-SUM(AG21:AI21) -> 500
A22: =ROW()-6 -> 16 | B22: =R22 -> EMK316BBJ476ML-T | C22: L1-PCBA | D22: =$D$4 -> Board RK3562 | E22: =$J$2 -> Gerber_CAMBOX_RK3562_lot500_2505 | F22: =$J$3 -> BOM_CameraBox_2026-04-14 2205 | G22: C20, C196 | H22: Capacitor | I22: 16V 47uF X5R ±20% 1206 Multilayer Ceramic Capacitors MLCC - SMD/SMT ROHS | J22: 1206 | K22: SMD | L22: Mounted | M22: pcs | N22: 0 | O22: =$J$4 -> 500 | P22: =IF($N22="","",$N22*$O22) -> 0 | Q22: Taiyo Yuden | R22: EMK316BBJ476ML-T | U22: Approved | V22: Approval Required | W22: Normal / Low | X22: Released | Y22: XFEMS Buy | AA22: LCSC | AB22: Mã này bỏ không hàn | AC22: SL giảm từ 1 xuống 0 : C20 DNP,Thêm C196 : DNP | AE22: =VLOOKUP(R22,'[1]VNSH03 gia thanh sx '!$F$6:$G$171,2,0) -> 500 | AF22: =P22-AE22 -> -500 | AG22: =IF(VLOOKUP(R22,'VNET-XF-2105'!$B$12:$D$145,3,0)>=P22,P22,VLOOKUP(R22,'VNET-XF-2105'!$B$12:$D$145,3,0)) -> 0 | AJ22: =P22-SUM(AG22:AI22) -> 0
A23: =ROW()-6 -> 17 | B23: =R23 -> CC0603KRX7R9BB474 | C23: L1-PCBA | D23: =$D$4 -> Board RK3562 | E23: =$J$2 -> Gerber_CAMBOX_RK3562_lot500_2505 | F23: =$J$3 -> BOM_CameraBox_2026-04-14 2205 | G23: C23 | H23: Capacitor | I23: 50V 470nF X7R ±10% 0603 Multilayer Ceramic Capacitors MLCC - SMD/SMT ROHS | J23: 0603 | K23: SMD | L23: Mounted | M23: pcs | N23: 1 | O23: =$J$4 -> 500 | P23: =IF($N23="","",$N23*$O23) -> 500 | Q23: Yageo | R23: CC0603KRX7R9BB474 | U23: Approved | V23: Approval Required | W23: Normal / Low | X23: Released | Y23: XFEMS Buy | AA23: LCSC | AE23: =VLOOKUP(R23,'[1]VNSH03 gia thanh sx '!$F$6:$G$171,2,0) -> 500 | AF23: =P23-AE23 -> 0 | AG23: =IF(VLOOKUP(R23,'VNET-XF-2105'!$B$12:$D$145,3,0)>=P23,P23,VLOOKUP(R23,'VNET-XF-2105'!$B$12:$D$145,3,0)) -> 495 | AJ23: =P23-SUM(AG23:AI23) -> 5
A24: =ROW()-6 -> 18 | B24: =R24 -> CC0603KRX7R9BB561 | C24: L1-PCBA | D24: =$D$4 -> Board RK3562 | E24: =$J$2 -> Gerber_CAMBOX_RK3562_lot500_2505 | F24: =$J$3 -> BOM_CameraBox_2026-04-14 2205 | G24: C24 | H24: Capacitor | I24: 560 pF ±10% 50V Ceramic Capacitor X7R 0603 (1608 Metric) | J24: 0603 | K24: SMD | L24: Mounted | M24: pcs | N24: 1 | O24: =$J$4 -> 500 | P24: =IF($N24="","",$N24*$O24) -> 500 | Q24: Yageo | R24: CC0603KRX7R9BB561 | U24: Approved | V24: Approval Required | W24: Normal / Low | X24: Released | Y24: XFEMS Buy | AA24: LCSC | AE24: =VLOOKUP(R24,'[1]VNSH03 gia thanh sx '!$F$6:$G$171,2,0) -> 500 | AF24: =P24-AE24 -> 0 | AG24: =IF(VLOOKUP(R24,'VNET-XF-2105'!$B$12:$D$145,3,0)>=P24,P24,VLOOKUP(R24,'VNET-XF-2105'!$B$12:$D$145,3,0)) -> 495 | AJ24: =P24-SUM(AG24:AI24) -> 5
A25: =ROW()-6 -> 19 | B25: =R25 -> CC0603JRNPO9BN750 | C25: L1-PCBA | D25: =$D$4 -> Board RK3562 | E25: =$J$2 -> Gerber_CAMBOX_RK3562_lot500_2505 | F25: =$J$3 -> BOM_CameraBox_2026-04-14 2205 | G25: C26 | H25: Capacitor | I25: 50V 75pF NP0 ±5% 0603 Multilayer Ceramic Capacitors MLCC - SMD/SMT ROHS | J25: 0603 | K25: SMD | L25: Mounted | M25: pcs | N25: 1 | O25: =$J$4 -> 500 | P25: =IF($N25="","",$N25*$O25) -> 500 | Q25: Yageo | R25: CC0603JRNPO9BN750 | U25: Approved | V25: Approval Required | W25: Normal / Low | X25: Released | Y25: XFEMS Buy | AA25: LCSC | AE25: =VLOOKUP(R25,'[1]VNSH03 gia thanh sx '!$F$6:$G$171,2,0) -> 500 | AF25: =P25-AE25 -> 0 | AG25: =IF(VLOOKUP(R25,'VNET-XF-2105'!$B$12:$D$145,3,0)>=P25,P25,VLOOKUP(R25,'VNET-XF-2105'!$B$12:$D$145,3,0)) -> 495 | AJ25: =P25-SUM(AG25:AI25) -> 5
A26: =ROW()-6 -> 20 | B26: =R26 -> CC0603KRX7R9BB563 | C26: L1-PCBA | D26: =$D$4 -> Board RK3562 | E26: =$J$2 -> Gerber_CAMBOX_RK3562_lot500_2505 | F26: =$J$3 -> BOM_CameraBox_2026-04-14 2205 | G26: C27 | H26: Capacitor | I26: 50V 56nF X7R ±10% 0603 Multilayer Ceramic Capacitors MLCC - SMD/SMT ROHS | J26: 0603 | K26: SMD | L26: Mounted | M26: pcs | N26: 1 | O26: =$J$4 -> 500 | P26: =IF($N26="","",$N26*$O26) -> 500 | Q26: Yageo | R26: CC0603KRX7R9BB563 | U26: Approved | V26: Approval Required | W26: Normal / Low | X26: Released | Y26: XFEMS Buy | AA26: LCSC | AE26: =VLOOKUP(R26,'[1]VNSH03 gia thanh sx '!$F$6:$G$171,2,0) -> 500 | AF26: =P26-AE26 -> 0 | AG26: =IF(VLOOKUP(R26,'VNET-XF-2105'!$B$12:$D$145,3,0)>=P26,P26,VLOOKUP(R26,'VNET-XF-2105'!$B$12:$D$145,3,0)) -> 495 | AJ26: =P26-SUM(AG26:AI26) -> 5
A27: =ROW()-6 -> 21 | B27: =R27 -> CC0402FRNPO9BN101 | C27: L1-PCBA | D27: =$D$4 -> Board RK3562 | E27: =$J$2 -> Gerber_CAMBOX_RK3562_lot500_2505 | F27: =$J$3 -> BOM_CameraBox_2026-04-14 2205 | G27: C28, C29, C40, C41, C44, C143, C152, C153, C161, C162 | H27: Capacitor | I27: 50V 100pF NP0 ±1% 0402 Multilayer Ceramic Capacitors MLCC - SMD/SMT ROHS | J27: 0402 | K27: SMD | L27: Mounted | M27: pcs | N27: 9 | O27: =$J$4 -> 500 | P27: =IF($N27="","",$N27*$O27) -> 4500 | Q27: Yageo | R27: CC0402FRNPO9BN101 | U27: Approved | V27: Approval Required | W27: Normal / Low | X27: Released | Y27: XFEMS Buy | AA27: LCSC | AC27: SL giảm 11 xuống 9, DNP C194,C29 | AE27: =VLOOKUP(R27,'[1]VNSH03 gia thanh sx '!$F$6:$G$171,2,0) -> 4000 | AF27: =P27-AE27 -> 500 | AG27: =IF(VLOOKUP(R27,'VNET-XF-2105'!$B$12:$D$145,3,0)>=P27,P27,VLOOKUP(R27,'VNET-XF-2105'!$B$12:$D$145,3,0)) -> 3945 | AH27: =IF(VLOOKUP(R27,'VNET-XF_dự kiến lần 2'!$B$2:$D$42,3,0)>=(P27-AG27),(P27-AG27),VLOOKUP(R27,'VNET-XF_dự kiến lần 2'!$B$2:$D$42,3,0)) -> 555 | AJ27: =P27-SUM(AG27:AI27) -> 0
A28: =ROW()-6 -> 22 | B28: =R28 -> C0603X7R104K500NT | C28: L1-PCBA | D28: =$D$4 -> Board RK3562 | E28: =$J$2 -> Gerber_CAMBOX_RK3562_lot500_2505 | F28: =$J$3 -> BOM_CameraBox_2026-04-14 2205 | G28: C30 | H28: Capacitor | I28: CAP CER 0.1UF 50V X7R 0603 | J28: 0603 | K28: SMD | L28: Mounted | M28: pcs | N28: 1 | O28: =$J$4 -> 500 | P28: =IF($N28="","",$N28*$O28) -> 500 | Q28: Hottech | R28: C0603X7R104K500NT | U28: Approved | V28: Approval Required | W28: Normal / Low | X28: Released | Y28: XFEMS Buy | AA28: LCSC | AE28: =VLOOKUP(R28,'[1]VNSH03 gia thanh sx '!$F$6:$G$171,2,0) -> 500 | AF28: =P28-AE28 -> 0 | AG28: =IF(VLOOKUP(R28,'VNET-XF-2105'!$B$12:$D$145,3,0)>=P28,P28,VLOOKUP(R28,'VNET-XF-2105'!$B$12:$D$145,3,0)) -> 500 | AH28: =IF(VLOOKUP(R28,'VNET-XF_dự kiến lần 2'!$B$2:$D$42,3,0)>=(P28-AG28),(P28-AG28),VLOOKUP(R28,'VNET-XF_dự kiến lần 2'!$B$2:$D$42,3,0)) -> 0 | AJ28: =P28-SUM(AG28:AI28) -> 0
A29: =ROW()-6 -> 23 | B29: =R29 -> C0805X5R106K160NT | C29: L1-PCBA | D29: =$D$4 -> Board RK3562 | E29: =$J$2 -> Gerber_CAMBOX_RK3562_lot500_2505 | F29: =$J$3 -> BOM_CameraBox_2026-04-14 2205 | G29: C31, C38, C55, C70, C71, C81, C83, C85, C90, C92, C95, C101, C104, C107, C110, C112, C115, C117, C122, C123, C136, C138, C155, C165, C168, C185, C188, C190 | H29: Capacitor | I29: CAP CER 10uF 16V X5R 0805 | J29: 0805 | K29: SMD | L29: Mounted | M29: pcs | N29: 28 | O29: =$J$4 -> 500 | P29: =IF($N29="","",$N29*$O29) -> 14000 | Q29: Hottech | R29: C0805X5R106K160NT | S29: FH | T29: 0805X106K160NT | U29: Approved | V29: Approval Required | W29: Normal / Low | X29: Released | Y29: XFEMS Buy | AA29: LCSC | AC29: Part 2 có 13360pcs | AE29: =VLOOKUP(R29,'[1]VNSH03 gia thanh sx '!$F$6:$G$171,2,0) -> 13500 | AF29: =P29-AE29 -> 500 | AG29: 13360 | AH29: =IF(VLOOKUP(R29,'VNET-XF_dự kiến lần 2'!$B$2:$D$42,3,0)>=(P29-AG29),(P29-AG29),VLOOKUP(R29,'VNET-XF_dự kiến lần 2'!$B$2:$D$42,3,0)) -> 500 | AJ29: =P29-SUM(AG29:AI29) -> 140
A30: =ROW()-6 -> 24 | B30: =R30 -> C0603X5R475K350NT | C30: L1-PCBA | D30: =$D$4 -> Board RK3562 | E30: =$J$2 -> Gerber_CAMBOX_RK3562_lot500_2505 | F30: =$J$3 -> BOM_CameraBox_2026-04-14 2205 | G30: C34, C36, C157 | H30: Capacitor | I30: 4.7uF 35V ±10% 0603 Multilayer Ceramic Capacitors MLCC - SMD/SMT ROHS | K30: SMD | L30: Mounted | M30: pcs | N30: 3 | O30: =$J$4 -> 500 | P30: =IF($N30="","",$N30*$O30) -> 1500 | Q30: SANYEAR | R30: C0603X5R475K350NT | U30: Approved | V30: Approval Required | W30: Normal / Low | X30: Released | Y30: XFEMS Buy | AA30: LCSC | AE30: =VLOOKUP(R30,'[1]VNSH03 gia thanh sx '!$F$6:$G$171,2,0) -> 1500 | AF30: =P30-AE30 -> 0 | AG30: =IF(VLOOKUP(R30,'VNET-XF-2105'!$B$12:$D$145,3,0)>=P30,P30,VLOOKUP(R30,'VNET-XF-2105'!$B$12:$D$145,3,0)) -> 1485 | AJ30: =P30-SUM(AG30:AI30) -> 15
A31: =ROW()-6 -> 25 | B31: =R31 -> CL05C330JB5NNNC | C31: L1-PCBA | D31: =$D$4 -> Board RK3562 | E31: =$J$2 -> Gerber_CAMBOX_RK3562_lot500_2505 | F31: =$J$3 -> BOM_CameraBox_2026-04-14 2205 | G31: C46, C47, C149, C150, C151, C159, C176, C177 | H31: Capacitor | I31: C0G 33pF 50V ±5% 0402 Multilayer Ceramic Capacitors MLCC - SMD/SMT ROHS | J31: 0402 | K31: SMD | L31: Mounted | M31: pcs | N31: 8 | O31: =$J$4 -> 500 | P31: =IF($N31="","",$N31*$O31) -> 4000 | Q31: Samsung Electro-Mechanics | R31: CL05C330JB5NNNC | U31: Approved | V31: Approval Required | W31: Normal / Low | X31: Released | Y31: XFEMS Buy | AA31: LCSC | AE31: =VLOOKUP(R31,'[1]VNSH03 gia thanh sx '!$F$6:$G$171,2,0) -> 4000 | AF31: =P31-AE31 -> 0 | AG31: =IF(VLOOKUP(R31,'VNET-XF-2105'!$B$12:$D$145,3,0)>=P31,P31,VLOOKUP(R31,'VNET-XF-2105'!$B$12:$D$145,3,0)) -> 3960 | AJ31: =P31-SUM(AG31:AI31) -> 40
A32: =ROW()-6 -> 26 | B32: =R32 -> CL10A226MQ8NRNE | C32: L1-PCBA | D32: =$D$4 -> Board RK3562 | E32: =$J$2 -> Gerber_CAMBOX_RK3562_lot500_2505 | F32: =$J$3 -> BOM_CameraBox_2026-04-14 2205 | G32: C53 | H32: Capacitor | I32: CAP CER 22UF 6.3V X5R 0603 | J32: 0603 | K32: SMD | L32: Mounted | M32: pcs | N32: 1 | O32: =$J$4 -> 500 | P32: =IF($N32="","",$N32*$O32) -> 500 | Q32: Samsung Electro-Mechanics | R32: CL10A226MQ8NRNE | U32: Approved | V32: Approval Required | W32: Normal / Low | X32: Released | Y32: XFEMS Buy | AA32: LCSC | AE32: =VLOOKUP(R32,'[1]VNSH03 gia thanh sx '!$F$6:$G$171,2,0) -> 500 | AF32: =P32-AE32 -> 0 | AG32: =IF(VLOOKUP(R32,'VNET-XF-2105'!$B$12:$D$145,3,0)>=P32,P32,VLOOKUP(R32,'VNET-XF-2105'!$B$12:$D$145,3,0)) -> 495 | AJ32: =P32-SUM(AG32:AI32) -> 5
A33: =ROW()-6 -> 27 | B33: =R33 -> C1206X5R106K500NT | C33: L1-PCBA | D33: =$D$4 -> Board RK3562 | E33: =$J$2 -> Gerber_CAMBOX_RK3562_lot500_2505 | F33: =$J$3 -> BOM_CameraBox_2026-04-14 2205 | G33: C105 | H33: Capacitor | I33: CAP CER 10uF 50V X5R 1206 | J33: 1206 | K33: SMD | L33: Mounted | M33: pcs | N33: 1 | O33: =$J$4 -> 500 | P33: =IF($N33="","",$N33*$O33) -> 500 | Q33: Hottech | R33: C1206X5R106K500NT | U33: Approved | V33: Approval Required | W33: Normal / Low | X33: Released | Y33: XFEMS Buy | AA33: LCSC | AE33: =VLOOKUP(R33,'[1]VNSH03 gia thanh sx '!$F$6:$G$171,2,0) -> 500 | AF33: =P33-AE33 -> 0 | AJ33: =P33-SUM(AG33:AI33) -> 500
A34: =ROW()-6 -> 28 | B34: =R34 -> CC0402FRNPO9BN120 | C34: L1-PCBA | D34: =$D$4 -> Board RK3562 | E34: =$J$2 -> Gerber_CAMBOX_RK3562_lot500_2505 | F34: =$J$3 -> BOM_CameraBox_2026-04-14 2205 | G34: C133, C134 | H34: Capacitor | I34: 50V 12pF NP0 ±1% 0402 Multilayer Ceramic Capacitors MLCC - SMD/SMT ROHS | J34: 0402 | K34: SMD | L34: Mounted | M34: pcs | N34: 2 | O34: =$J$4 -> 500 | P34: =IF($N34="","",$N34*$O34) -> 1000 | Q34: Yageo | R34: CC0402FRNPO9BN120 | U34: Approved | V34: Approval Required | W34: Normal / Low | X34: Released | Y34: XFEMS Buy | AA34: LCSC | AE34: =VLOOKUP(R34,'[1]VNSH03 gia thanh sx '!$F$6:$G$171,2,0) -> 1000 | AF34: =P34-AE34 -> 0 | AG34: =IF(VLOOKUP(R34,'VNET-XF-2105'!$B$12:$D$145,3,0)>=P34,P34,VLOOKUP(R34,'VNET-XF-2105'!$B$12:$D$145,3,0)) -> 990 | AJ34: =P34-SUM(AG34:AI34) -> 10
A35: =ROW()-6 -> 29 | B35: =R35 -> EMK325ABJ107MM-T | C35: L1-PCBA | D35: =$D$4 -> Board RK3562 | E35: =$J$2 -> Gerber_CAMBOX_RK3562_lot500_2505 | F35: =$J$3 -> BOM_CameraBox_2026-04-14 2205 | G35: C140, C146 | H35: Capacitor | I35: 100uF ±20% 16V Ceramic Capacitor X5R 1210 | J35: 1210 | K35: SMD | L35: Mounted | M35: pcs | N35: 2 | O35: =$J$4 -> 500 | P35: =IF($N35="","",$N35*$O35) -> 1000 | Q35: Taiyo Yuden | R35: EMK325ABJ107MM-T | U35: Approved | V35: Approval Required | W35: Normal / Low | X35: Released | Y35: XFEMS Buy | AA35: LCSC | AE35: =VLOOKUP(R35,'[1]VNSH03 gia thanh sx '!$F$6:$G$171,2,0) -> 1000 | AF35: =P35-AE35 -> 0 | AG35: =IF(VLOOKUP(R35,'VNET-XF-2105'!$B$12:$D$145,3,0)>=P35,P35,VLOOKUP(R35,'VNET-XF-2105'!$B$12:$D$145,3,0)) -> 500 | AH35: =IF(VLOOKUP(R35,'VNET-XF_dự kiến lần 2'!$B$2:$D$42,3,0)>=(P35-AG35),(P35-AG35),VLOOKUP(R35,'VNET-XF_dự kiến lần 2'!$B$2:$D$42,3,0)) -> 500 | AJ35: =P35-SUM(AG35:AI35) -> 0
A36: =ROW()-6 -> 30 | B36: =R36 -> 0805CG330J500NT | C36: L1-PCBA | D36: =$D$4 -> Board RK3562 | E36: =$J$2 -> Gerber_CAMBOX_RK3562_lot500_2505 | F36: =$J$3 -> BOM_CameraBox_2026-04-14 2205 | G36: C141 | H36: Capacitor | I36: 50V 33pF C0G ±5% 0805 Multilayer Ceramic Capacitors MLCC - SMD/SMT ROHS | J36: 0805 | K36: SMD | L36: Mounted | M36: pcs | N36: 1 | O36: =$J$4 -> 500 | P36: =IF($N36="","",$N36*$O36) -> 500 | Q36: FH(Guangdong Fenghua Advanced Tech) | R36: 0805CG330J500NT | U36: Approved | V36: Approval Required | W36: Normal / Low | X36: Released | Y36: XFEMS Buy | AA36: LCSC | AE36: =VLOOKUP(R36,'[1]VNSH03 gia thanh sx '!$F$6:$G$171,2,0) -> 1000 | AF36: =P36-AE36 -> -500 | AG36: =IF(VLOOKUP(R36,'VNET-XF-2105'!$B$12:$D$145,3,0)>=P36,P36,VLOOKUP(R36,'VNET-XF-2105'!$B$12:$D$145,3,0)) -> 495 | AJ36: =P36-SUM(AG36:AI36) -> 5
A37: =ROW()-6 -> 31 | B37: =R37 -> FN21N100J500PAG | C37: L1-PCBA | D37: =$D$4 -> Board RK3562 | E37: =$J$2 -> Gerber_CAMBOX_RK3562_lot500_2505 | F37: =$J$3 -> BOM_CameraBox_2026-04-14 2205 | G37: C142 | H37: Capacitor | I37: 50V 10pF C0G ±5% 0805 Multilayer Ceramic Capacitors MLCC - SMD/SMT ROHS | J37: 0805 | K37: SMD | L37: Mounted | M37: pcs | N37: 1 | O37: =$J$4 -> 500 | P37: =IF($N37="","",$N37*$O37) -> 500 | Q37: PSA(Prosperity Dielectrics) | R37: FN21N100J500PAG | U37: Approved | V37: Approval Required | W37: Normal / Low | X37: Released | Y37: XFEMS Buy | AA37: LCSC | AE37: =VLOOKUP(R37,'[1]VNSH03 gia thanh sx '!$F$6:$G$171,2,0) -> 500 | AF37: =P37-AE37 -> 0 | AG37: =IF(VLOOKUP(R37,'VNET-XF-2105'!$B$12:$D$145,3,0)>=P37,P37,VLOOKUP(R37,'VNET-XF-2105'!$B$12:$D$145,3,0)) -> 495 | AJ37: =P37-SUM(AG37:AI37) -> 5
A38: =ROW()-6 -> 32 | B38: =R38 -> CCTC TCC1206X7R225K101HT | C38: L1-PCBA | D38: =$D$4 -> Board RK3562 | E38: =$J$2 -> Gerber_CAMBOX_RK3562_lot500_2505 | F38: =$J$3 -> BOM_CameraBox_2026-04-14 2205 | G38: C195 | H38: Capacitor | I38: 100V 2.2uF X7R ±10% 1206 Multilayer Ceramic Capacitors MLCC - SMD/SMT ROHS | J38: 1206 | K38: SMD | L38: Mounted | M38: pcs | N38: 1 | O38: =$J$4 -> 500 | P38: =IF($N38="","",$N38*$O38) -> 500 | Q38: CCTC | R38: CCTC TCC1206X7R225K101HT | U38: Approved | V38: Approval Required | W38: Normal / Low | X38: Released | Y38: XFEMS Buy | AA38: LCSC | AC38: SL thêm 1:Thêm C195 | AE38: =VLOOKUP(R38,'[1]VNSH03 gia thanh sx '!$F$6:$G$171,2,0) -> #REF! | AF38: =P38-AE38 -> #REF! | AJ38: =P38-SUM(AG38:AI38) -> 500
A39: =ROW()-6 -> 33 | B39: =R39 -> CL10A225KQ8NNNC | C39: L1-PCBA | D39: =$D$4 -> Board RK3562 | E39: =$J$2 -> Gerber_CAMBOX_RK3562_lot500_2505 | F39: =$J$3 -> BOM_CameraBox_2026-04-14 2205 | G39: C154 | H39: Capacitor | I39: 2.2uF ±10% 6.3V X5R 0603 Multilayer Ceramic Capacitors MLCC - SMD/SMT RoHS | J39: 0603 | K39: SMD | L39: Mounted | M39: pcs | N39: 1 | O39: =$J$4 -> 500 | P39: =IF($N39="","",$N39*$O39) -> 500 | Q39: Samsung Electro-Mechanics | R39: CL10A225KQ8NNNC | U39: Approved | V39: Approval Required | W39: Normal / Low | X39: Released | Y39: XFEMS Buy | AA39: LCSC | AE39: =VLOOKUP(R39,'[1]VNSH03 gia thanh sx '!$F$6:$G$171,2,0) -> 500 | AF39: =P39-AE39 -> 0 | AG39: =IF(VLOOKUP(R39,'VNET-XF-2105'!$B$12:$D$145,3,0)>=P39,P39,VLOOKUP(R39,'VNET-XF-2105'!$B$12:$D$145,3,0)) -> 495 | AJ39: =P39-SUM(AG39:AI39) -> 5
A40: =ROW()-6 -> 34 | B40: =R40 -> CL05A105KO5NNNC | C40: L1-PCBA | D40: =$D$4 -> Board RK3562 | E40: =$J$2 -> Gerber_CAMBOX_RK3562_lot500_2505 | F40: =$J$3 -> BOM_CameraBox_2026-04-14 2205 | G40: C170, C174, C199 | H40: Capacitor | I40: 16V 1uF X5R ±10% 0402 Multilayer Ceramic Capacitors MLCC - SMD/SMT ROHS | J40: 0402 | K40: SMD | L40: Mounted | M40: pcs | N40: 3 | O40: =$J$4 -> 500 | P40: =IF($N40="","",$N40*$O40) -> 1500 | Q40: Samsung Electro-Mechanics | R40: CL05A105KO5NNNC | U40: Approved | V40: Approval Required | W40: Normal / Low | X40: Released | Y40: XFEMS Buy | AA40: LCSC | AC40: SL tăng 2 lên 3: Thêm C199 | AE40: =VLOOKUP(R40,'[1]VNSH03 gia thanh sx '!$F$6:$G$171,2,0) -> 1000 | AF40: =P40-AE40 -> 500 | AG40: =IF(VLOOKUP(R40,'VNET-XF-2105'!$B$12:$D$145,3,0)>=P40,P40,VLOOKUP(R40,'VNET-XF-2105'!$B$12:$D$145,3,0)) -> 990 | AJ40: =P40-SUM(AG40:AI40) -> 510
...

Sheet REF
A1: Logic thứ tự cột: Thông tin BOM → thông tin thiết kế → thông tin kỹ thuật linh kiện → trạng thái lắp → số lượng → PN/AVL → kiểm soát thay thế → release/supply/sourcing → note/datasheet
A2: No | B2: Column | C2: Meaning / Ý nghĩa | D2: Giá trị cần điền | E2: Ví dụ | F2: Bắt buộc | G2: Dropdown list | H2: Note | J2: BOM Level | K2: Category | L2: Mounting Type | M2: Mount Status | N2: Unit | O2: AVL Status | P2: Substitution Rule | Q2: Critical Level | R2: Release Status | S2: Supply Type | T2: Ref Supplier
A3: =ROW()-2 -> 1 | B3: No | C3: Số thứ tự dòng BOM | D3: Số tăng dần, không trùng | E3: 1, 2, 3 | F3: Có | J3: L1-PCBA | K3: Resistor | L3: SMD | M3: Mounted | N3: pcs | O3: Approved | P3: No Substitute | Q3: Important / High | R3: Draft | S3: XFEMS Buy | T3: DigiKey
A4: =ROW()-2 -> 2 | B4: BOM Level | C4: Cấp BOM, dùng cho BOM đa cấp | D4: Chọn theo dropdown: L1-PCBA, L2-Box, L3-Acc | E4: L1-PCBA | F4: Có | G4: L1-PCBA, L2-BOX, L3-ACC, L4-PCK | J4: L2-BOX | K4: Capacitor | L4: TH | M4: Do Not Process | N4: set | O4: Not Yet Approved | P4: Approval Required | Q4: Normal / Low | R4: For Quote | S4: Customer Supplied | T4: Mouser
A5: =ROW()-2 -> 3 | B5: Board Name | C5: Tên bo mạch/module chứa linh kiện | D5: Tên board theo thiết kế | E5: Main Board, IO Board | F5: Có | J5: L3-ACC | K5: Inductor | L5: ASM | N5: m | O5: Customer Specified | R5: Released | S5: Do Not Buy | T5: LCSC
A6: =ROW()-2 -> 4 | B6: PCB Rev | C6: Phiên bản PCB/layout | D6: Theo revision layout đã release | E6: Rev.A, Rev.B | F6: Có | K6: Ferrite Bead | N6: cm | S6: Consigned | T6: Arrow
A7: =ROW()-2 -> 5 | B7: BOM Rev | C7: Phiên bản BOM | D7: Theo version BOM phát hành | E7: Rev.A.01 | F7: Có | K7: Diode | N7: mm | T7: Avnet
A8: =ROW()-2 -> 6 | B8: RefDes / Designator | C8: Vị trí linh kiện trên PCB | D8: Ghi đầy đủ designator, có thể gom nhiều vị trí cùng spec | E8: R1,R2,R3 hoặc U1 | F8: Có | K8: LED | N8: roll | T8: TME
A9: =ROW()-2 -> 7 | B9: Category | C9: Nhóm linh kiện | D9: Chọn theo dropdown | E9: Resistor, Capacitor, IC, Connector | F9: Có | K9: Transistor | N9: panel | T9: RS
A10: =ROW()-2 -> 8 | B10: Description | C10: Mô tả kỹ thuật ngắn gọn | D10: Mô tả đủ để sourcing hiểu đúng | E10: Resistor 10k ±1% 0603 | F10: Có | K10: IC | N10: pair | T10: Farnell
A11: =ROW()-2 -> 9 | B11: Package / Footprint | C11: Package/footprint theo layout | D11: Phải khớp footprint PCB Chỉ cần điền các con nhỏ, như 0402, 0603, 0805, 1206 | E11: 0603, SOT-23, QFN-48 | F11: Có | K11: Crystal/Oscillator | N11: box
A12: =ROW()-2 -> 10 | B12: Mounting Type | C12: Kiểu lắp ráp | D12: Chọn theo dropdown: SMD, THT, ASM, ME | E12: SMD, THT, ASM, Mechanical | F12: Có | G12: SMD, THT, ASM, ME | K12: Thermistor | N12: bag
A13: =ROW()-2 -> 11 | B13: Mount Status | C13: Trạng thái có lắp hay không | D13: Chọn theo dropdown: Mounted, Do Not Process, Optional | E13: Mounted, DNP, Optional | F13: Có | G13: Mounted, Do Not Process, Optional | K13: Speaker
A14: =ROW()-2 -> 12 | B14: Unit | C14: Đơn vị tính | D14: pcs, set, m, roll… | E14: pcs | F14: Có | K14: Sensor
A15: =ROW()-2 -> 13 | B15: Qty/Set | C15: Số lượng linh kiện dùng cho 1 board/set | D15: Số lượng thực tế theo thiết kế | E15: 1, 2, 4 | F15: Có | K15: Connector
A16: =ROW()-2 -> 14 | B16: Board Qty | C16: Số lượng board/set cần sản xuất | D16: Nhập theo lot sản xuất hoặc kế hoạch mẫu | E16: 10, 100, 1000 | F16: Có | K16: Module
A17: =ROW()-2 -> 15 | B17: Total Engineer Qty | C17: Tổng số lượng kỹ thuật trước khi tính hao hụt/MOQ/SPQ | D17: Công thức = Qty/Set × Board Qty, loại trừ DNP/Do Not Buy nếu có | E17: 20 | F17: Có | K17: Switch/Button
A18: =ROW()-2 -> 16 | B18: Manufacturer 1 | C18: Hãng của mã ưu tiên PN1 | D18: Tên hãng sản xuất linh kiện | E18: Yageo, TI, ST, Murata | F18: Có nếu có PN1 | H18: Mua hàng ưu tiên mua mã 1 | K18: Relay
A19: =ROW()-2 -> 17 | B19: PN1 | C19: Mã linh kiện ưu tiên mua | D19: Full Manufacturer Part Number, không ghi tắt | E19: RC0603FR-0710KL | F19: Có | K19: Fuse/Protection
A20: =ROW()-2 -> 18 | B20: Manufacturer 2 | C20: Hãng của mã thay thế PN2 | D20: Tên hãng sản xuất thay thế | E20: UniOhm, Walsin, Samsung | F20: Nên có | K20: PCB
A21: =ROW()-2 -> 19 | B21: PN2 | C21: Mã linh kiện thay thế | D21: Full Manufacturer Part Number thay thế đã được kỹ sư đề xuất | E21: 0603WAF1002T5E | F21: Nên có | K21: Stencil
A22: =ROW()-2 -> 20 | B22: AVL Status | C22: Trạng thái phê duyệt mã linh kiện | D22: Chọn theo dropdown | E22: Approved, Conditional, Not Yet Approved | F22: Có | G22: Approved Conditional Customer Specified Not Yet Approved | K22: Cable/Harness
A23: =ROW()-2 -> 21 | B23: Substitution Rule | C23: Quy tắc thay thế linh kiện | D23: Chọn theo dropdown | E23: No Substitute, Approved AVL Only | F23: Có | G23: Approval Required Same spec Allowed No Substitute | K23: Label/Packaging
A24: =ROW()-2 -> 22 | B24: Critical Level | C24: Mức độ quan trọng của linh kiện | D24: Chọn theo dropdown | E24: A-Critical, B-Important, C-Normal | F24: Có | G24: A-Critical B-Important C-Normal D-Commodity | K24: Others
