Workbook

Sheet Sheet1
A2: Tháng 9
A3: Thông Tin Thiết Bị
A4: STT/ ThángA4:Q4 | C4: Ngày Nhận | D4: Ngày Trả | E4: Model | F4: IMEI hoặc S/L | G4: Phụ Kiện | H4: Hạn BH | I4: Chị Hà Note | J4: Chị Phí Linh Kiện Thay Thế | K4: Ghi Chú | L4: Cấu Hình IP, PORT | M4: FW Ver. Cũ | N4: FW Ver. Mới | O4: Xác Định Lỗi | P4: Xử Lý Lỗi | Q4: Nhân Viên BH
A5: 1 | B5: ĐL. Ngọc Hoàn | C5: 46268 | D5: 46268 | E5: VNSH02 | F5: 0032002AD9 | G5: SIM + thẻ nhớ | H5: H | O5: SIM nhận chập chờn, mất nguồn ra RS232 | P5: Xử lý lại khay SIM, xử lý lại nguồn ra RS232 | Q5: Tùng
A6: 2 | C6: 46268 | D6: 46279 | E6: VNSH03 | F6: VNET861385071456282 | H6: Còn BH | K6: ID mới: VNET861385070647584 | N6: VNSH03.1.0.20260805 | O6: LED trạng thái không hiển thị | P6: Đổi bảo hành, thiết bị lỗi BH giữ lại gửi qua Aithings bảo hành | Q6: Tùng
A7: 3 | C7: 46274 | D7: 46279 | E7: VNSH02 | F7: 0032001EFD | O7: Thẻ nhớ lỗi lắp vào lúc có nguồn lúc không | P7: Thay thẻ nhớ khác test lại hoạt động bình thường | Q7: Tùng
A8: 4 | C8: 46274 | D8: 46283 | E8: 51_TG102LE(upg) | F8: 005106075423457 | H8: Còn BH | L8: 125.212.203.50:13579 | N8: LEu.2.0-251205 | O8: Mất giao tiếp MCU-Module SIM, không nhận SIM Viettel | P8: Xử lý lại giao tiếp MCU-Module SIM, hạ FW về FW cũ update lại | Q8: Tùng
A9: 5 | C9: 46274 | D9: 46283 | E9: 51_TG102LE(upg) | F9: 005185070120301 | H9: H | L9: 125.212.203.50:13579 | N9: LEu.2.0-251205 | O9: Mất giao tiếp MCU-Module SIM, không nhận SIM Viettel | P9: Xử lý lại giao tiếp MCU-Module SIM, hạ về FW cũ nâng cấp lại FW mới | Q9: Tùng
A10: 6 | C10: 46274 | D10: 46283 | E10: 51_TG102LE(upg) | F10: 005185070137131 | H10: H | L10: 125.212.203.50:13579 | N10: LEu.2.0-251205 | O10: Mất giao tiếp | P10: Nạp lại FW | Q10: Tùng
A11: 7 | C11: 46274 | D11: 46283 | E11: 51_TG102LE(upg) | F11: 005185070128015 | G11: SIM | H11: H | L11: 125.212.203.50:13579 | N11: LEu.2.0-251205 | O11: Mất giao tiếp | P11: Nạp lại FW | Q11: Tùng
A12: 8 | C12: 46274 | D12: 46283 | E12: 51_TG102LE(upg) | F12: 005106075411551 | H12: Còn BH | L12: 125.212.203.50:13579 | N12: LEu.2.0-251205 | O12: Lỗi connector, SIM Viettel không kết nối chạm BTS, khay SIM chập chờn | P12: Thay connector, hạ FW nâng cấp lại, thay khay SIM | Q12: Tùng
A13: 9 | C13: 46274 | D13: 46289 | E13: 55_TG102LE | F13: 005505051232074 | K13: Hết hạn DV | L13: 125.212.203.50:13579 | N13: Le4.3.4-250402 | O13: Mất giao tiếp | P13: Nạp lại FW | Q13: Tùng
A14: 10 | C14: 46274 | D14: 46283 | E14: 51_TG102LE(upg) | F14: 005185070118743 | G14: SIM | H14: H | L14: 125.212.203.50:13579 | N14: LEu.2.0-251205 | O14: Mất giao tiếp, không nhận IC chuyển động | P14: Nạp lại FW, xử lý lại kết nối IC chuyển động với MCU | Q14: Tùng
A15: 11 | C15: 46274 | D15: 46283 | E15: 51_TG102LE(upg) | F15: 005106075433571 | H15: Còn BH | L15: 125.212.203.50:13579 | N15: LEu.2.0-251205 | O15: Không nhận SIM,(nhận SIM Viettel không kết nối tới trạm BTS) | P15: Xử lý lại VCC khay SIM, hạ về FW cũ nâng cấp lại FW mới | Q15: Tùng
A16: 12 | C16: 46274 | D16: 46283 | E16: 51_TG102LE(upg) | F16: 005185070132728 | H16: H | K16: ID mới: 005185070008167 | L16: 125.212.203.50:13579 | N16: LEu.2.0-251205 | O16: Không nhận SIM | P16: Thay module SIM | Q16: Tùng
A17: 13 | C17: 46274 | D17: 46283 | E17: 51_TG102LE(upg) | F17: 005185070144863 | G17: SIM | H17: Còn BH | K17: SIM lỗi | L17: 125.212.203.50:13579 | N17: LEu.2.0-251205 | O17: Mất giao tiếp Module SIM-MCU, khay SIM chập chờn | P17: Xử lý lại giao tiếp Module SIM MCU, thay khay SIM | Q17: Tùng
A18: 14 | C18: 46274 | D18: 46289 | E18: 51_TG102LE(upd) | F18: 005181051090695 | H18: Còn BH | O18: Mất giao tiếp | P18: Nạp lại FW | Q18: Tùng
A19: 15 | C19: 46274 | D19: 46289 | E19: 51_TG102LE(upd) | F19: 862205051196303 | G19: SIM | H19: H | K19: ID mới: 005105051196303, SIM lỗi, hết hạn DV | L19: 125.212.203.50:13579 | M19: Le4.1.05.AOO55.210624 | N19: LEu.2.0-251205 | O19: Mất giao tiếp MCU-Module SIM | P19: Nâng cấp FW thiết bị + module SIM | Q19: Tùng
A20: 16 | C20: 46274 | D20: 46289 | E20: 55_TG102LE | F20: 862205051205252 | H20: Không xác định | K20: ID mới: 005505051205252, hết hạn DV | N20: Le4.3.4.250402 | O20: Không xác định được lỗi | P20: Xoá bộ nhớ cấu hình lại thiết bị | Q20: Tùng
A21: 17 | C21: 46274 | D21: 46289 | E21: 55_TG102LE | F21: 862205051227322 | H21: Không xác định | K21: ID mới: 005505051227322 | M21: Le4.2.3.09230922 | N21: Le4.3.4.250402 | O21: Không xác định được lỗi | P21: Xoá bộ nhớ cấu hình lại thiết bị | Q21: Tùng
A22: 18 | C22: 46274 | D22: 46289 | E22: 60_TG102LE | F22: 006011074333824 | H22: Còn BH | K22: ID mới: 007785070692614 | L22: 125.212.203.115:13030 | M22: LEc.2.3-250327 | O22: Lỗi GPS | P22: Thay module SIM A7677S | Q22: Tùng
A23: 19 | C23: 46280 | D23: 46283 | E23: 51_TG102LE(upg) | F23: 005106075447985 | O23: Nhận SIM chập chờn | P23: Xử lý lại giao tiếp khay SIM - Module SIM | Q23: Tùng
A24: 20 | C24: 46280 | D24: 46289 | E24: 51_TG102LE(upg) | F24: 005185070138014 | H24: Còn BH | M24: LEu.2.0-251205 | O24: Nhận SIM chập chờn | P24: Xử lý lại giao tiếp Module SIM - khay SIM | Q24: Tùng
A25: 21 | C25: 46280 | D25: 46289 | E25: 51_TG102LE(upg) | F25: 005106075434207 | H25: Còn BH | O25: Không nhận SIM | P25: Xử lý lại giao tiếp Module - khay SIM | Q25: Tùng
A26: 22 | C26: 46280 | D26: 46289 | E26: 51_TG102LE(upg) | F26: 005185070138766 | G26: SIM | H26: Còn BH | M26: LEu.2.0-251205 | O26: Nhận SIM chập chờn | P26: Xử lý lại giao tiếp Module SIM - khay SIM | Q26: Tùng
A27: 23 | C27: 46280 | D27: 46289 | E27: 51_TG102LE(upg) | F27: 005185070128965 | H27: Còn BH | O27: Chập nguồn | P27: Thay diode quá áp | Q27: Tùng
A28: 24 | C28: 46280 | D28: 46289 | E28: 51_TG102LE(upg) | F28: 005111074333923 | H28: Còn BH | K28: ID mới: 005185070007722 | L28: 125.212.203.50,13579 | M28: LEu.2.0-251205 | N28: LEd.1.2.250416 | O28: Không nhận SIM | P28: Thay module SIM A7677S | Q28: Tùng
A29: 25 | C29: 46280 | D29: 46289 | E29: 51_TG102LE(upg) | F29: 005106075448470 | H29: Còn BH | M29: LEu.2.0-251205 | O29: Nhận SIM chập chờn | P29: Xử lý lại giao tiếp Module - khay SIM | Q29: Tùng
A30: 26 | C30: 46280 | D30: 46289 | E30: 51_TG102LE(upd) | F30: 862205051198481 | G30: SIM | H30: Không xác định | K30: Thiết bị xuất bán VIETCOM,ID mới: 005105051198481, SIM lỗi | L30: 125.212.203.50,13579 | M30: LEu.2.0-251205 | O30: Bo mạch oxi hoá | P30: Thay MCU, IC giao tiếp tụ trở connector, cổng DB09, nâng cấp FW thiết bị + mdodule SIM | Q30: Tùng
A31: 27 | C31: 46280 | D31: 46289 | E31: 55_TG102LE | F31: 862205051224725 | H31: Không xác định | K31: ID mới: 005505051224725 | L31: 125.212.203.50:13579 | O31: Mất giao tiếp | P31: Nạp lại FW | Q31: Tùng
A32: 28 | C32: 46280 | D32: 46289 | E32: 60_TG102LE | F32: 006011074329798 | H32: Còn BH | K32: ID mới: 007785070647717 | L32: 1.252122e+11 | M32: LEc.2.3.250327 | N32: LEd.1.2.250416 | O32: Lỗi GPS | P32: Thay module SIM A7677S | Q32: Tùng
A33: 29 | C33: 46280 | D33: 46289 | E33: VNSH02 | F33: WP22050219S03573 / 0032004D81 | G33: Thẻ nhớ | O33: Lỗi microphone | P33: Thay microphone | Q33: Tùng
A34: 30 | C34: 46280 | D34: 46283 | E34: VNSH02 | F34: WP21120135S02289 / 0032002422 | G34: SIM + thẻ nhớ | H34: H | L34: 1.252122e+11 | M34: V3.3.21.6_R23041202 / C43-M01-GD32-MCU-T23030101 | N34: V3.3.21.6_R23041202 / C43-M01-GD32-MCU-T23060699 | O34: Chập nguồn 5V | P34: Tách chập nguồn thay tụ lọc | Q34: Tùng
A35: 31 | C35: 46280 | D35: 46283 | E35: VNSH02 | F35: 0032002655 | G35: SIM + thẻ nhớ | H35: H | L35: 1.252122e+11 | M35: V3.3.21.6_R23041202 / C43-M01-GD32-MCU-T23030101 | N35: V3.3.21.6_R23041202 / C43-M01-GD32-MCU-T23060699 | O35: Chập nguồn 3v3 | P35: Tách chập nguồn thay tụ lọc, thay IC nguồn, nâng cấp FW MCU | Q35: Tùng
A36: 32 | C36: 46280 | D36: 46289 | E36: VNSH02 | F36: WP21110052S00947 / 0032000C17 | G36: Thẻ nhớ | H36: H | K36: Khách phản hồi lại SIM nhận chập chờn | L36: 125.212.203.91,21083 | M36: V3.3.21.6_R23041202 / C43-M01-GD32-MCU-T23030101 | O36: Khay SIM lỏng | P36: Gửi thêm miếng dán chèn SIM cho khách | Q36: Tùng
A37: 33 | C37: 46280 | D37: 46289 | E37: HUB_H1 | F37: 2002202300316 | H37: H | K37: Dùng cho TG102LE | O37: Không dò được nhiệt ACT2 | P37: Thay IC giao tiếp | Q37: Tùng
A38: 34 | C38: 46280 | D38: 46289 | E38: HUB_H1 | F38: 2002202300100 | H38: H | K38: Dùng cho TG102LE | O38: Không dò được nhiệt | P38: Nạp lại FW | Q38: Tùng
A39: 35 | C39: 46294 | E39: 51_TG102LE(upg) | F39: 005106075435139 | H39: H | O39: Thường xuyên mất giao tiếp MCU-Module SIM | Q39: Tùng
A40: 36 | C40: 46294 | E40: VNSH02 | F40: WP22050219S00296 / 0032004243 | H40: H | O40: Chập nguồn đầu vào | Q40: Tùng
A41: 37 | B41: Anh Tuấn BG | C41: 46268 | D41: 46270 | E41: VNSH02 | F41: 003200D967 | H41: Còn BH | O41: Chập nguồn 3v3 | P41: Tách chập nguồn thay tụ lọc | Q41: Tùng
...

Sheet TongHopXLBH_2503
A1: Báo Cáo Xử Lý Bảo Hành Tháng 09 / 2026
A3: Số lượng thiết bị nhận bảo hành | C3: Model | D3: Số lượng | E3: Tồn BH | F3: Ghi chú | G3: Số lượng thiết bị xử lý của nhân viên
C4: 51_TG102LE(upd) | D4: =COUNTIFS(Sheet1!E:E,TongHopXLBH_2503!C4) -> 41 | E4: =COUNTIFS(Sheet1!E:E,C4,Sheet1!D:D,"") -> 19 | F4: Phát sinh lỗi không nhận phôi SIM Viettel mới trên module A7670E | G4: Nguyễn Minh Tùng | I4: =COUNTIF(Sheet1!Q:Q,"Tùng") -> 85
C5: 51_TG102LE(upg) | D5: =COUNTIFS(Sheet1!E:E,TongHopXLBH_2503!C5) -> 44 | E5: =COUNTIFS(Sheet1!E:E,C5,Sheet1!D:D,"") -> 14 | F5: Phát sinh lỗi không nhận phôi SIM Viettel mới trên module A7670E | G5: Trần Văn Hậu | I5: =COUNTIF(Sheet1!Q:Q,"Hậu") -> 125
C6: 55_TG102LE | D6: =COUNTIFS(Sheet1!E:E,TongHopXLBH_2503!C6) -> 37 | E6: =COUNTIFS(Sheet1!E:E,C6,Sheet1!D:D,"") -> 13 | F6: Phát sinh lỗi không nhận phôi SIM Viettel mới trên module A7670E | G6: Đặng Văn Quang | I6: =COUNTIF(Sheet1!Q:Q,"Quang") -> 0
C7: 56_TG102LE | D7: =COUNTIFS(Sheet1!E:E,TongHopXLBH_2503!C7) -> 24 | E7: =COUNTIFS(Sheet1!E:E,C7,Sheet1!D:D,"") -> 23
C8: 86_TG102LE | D8: =COUNTIFS(Sheet1!E:E,TongHopXLBH_2503!C8) -> 4 | E8: =COUNTIFS(Sheet1!E:E,C8,Sheet1!D:D,"") -> 0 | F8: Phát sinh lỗi không nhận sim
C9: 60_TG102LE | D9: =COUNTIFS(Sheet1!E:E,TongHopXLBH_2503!C9) -> 23 | E9: =COUNTIFS(Sheet1!E:E,C9,Sheet1!D:D,"") -> 10 | F9: Phát sinh lỗi không nhận phôi SIM Viettel mới trên module A7672s
C10: 77_TG102LE | D10: =COUNTIFS(Sheet1!E:E,TongHopXLBH_2503!C10) -> 7 | E10: =COUNTIFS(Sheet1!E:E,C10,Sheet1!D:D,"") -> 2
C11: 80_TG102E | D11: =COUNTIFS(Sheet1!E:E,TongHopXLBH_2503!C11) -> 3 | E11: =COUNTIFS(Sheet1!E:E,C11,Sheet1!D:D,"") -> 2
C12: HUB_H1 | D12: =COUNTIFS(Sheet1!E:E,TongHopXLBH_2503!C12) -> 8 | E12: =COUNTIFS(Sheet1!E:E,C12,Sheet1!D:D,"") -> 6
C13: HUB_H2 | D13: =COUNTIFS(Sheet1!E:E,TongHopXLBH_2503!C13) -> 0 | E13: =COUNTIFS(Sheet1!E:E,C13,Sheet1!D:D,"") -> 0
C14: Card Reader | D14: =COUNTIFS(Sheet1!E:E,TongHopXLBH_2503!C14) -> 8 | E14: =COUNTIFS(Sheet1!E:E,C14,Sheet1!D:D,"") -> 7
C15: ACT-01 | D15: =COUNTIFS(Sheet1!E:E,TongHopXLBH_2503!C15) -> 3 | E15: =COUNTIFS(Sheet1!E:E,C15,Sheet1!D:D,"") -> 1
C16: VNSH01 | D16: =COUNTIFS(Sheet1!E:E,TongHopXLBH_2503!C16) -> 5 | E16: =COUNTIFS(Sheet1!E:E,C16,Sheet1!D:D,"") -> 2
C17: VNSH02 | D17: =COUNTIFS(Sheet1!E:E,TongHopXLBH_2503!C17) -> 47 | E17: =COUNTIFS(Sheet1!E:E,C17,Sheet1!D:D,"") -> 17
C18: VNSH03 | D18: =COUNTIFS(Sheet1!E:E,TongHopXLBH_2503!C18) -> 10 | E18: =COUNTIFS(Sheet1!E:E,C18,Sheet1!D:D,"") -> 8 | F18: Phát sinh lỗi không sáng đèn led
C19: ACT-01 | D19: =COUNTIFS(Sheet1!E:E,TongHopXLBH_2503!C19) -> 3
C20: EV04 | D20: =COUNTIFS(Sheet1!E:E,TongHopXLBH_2503!C20) -> 1 | E20: =COUNTIFS(Sheet1!E:E,C20,Sheet1!D:D,"") -> 0
C21: Phụ kiện | D21: =COUNTIFS(Sheet1!E:E,"*PK_*") -> 1 | E21: =COUNTIFS(Sheet1!E:E,C21,Sheet1!D:D,"") -> 0
C22: Tổng | D22: =SUM(D4:D21) -> 269 | E22: =SUM(E4:E21) -> 124
